Workbook
Name LP: #REF!

Sheet Sheet1
A1: EXPO | B1: Not Finish

Sheet Valuation Sheet
B1: Ticker | C1: Price | D1: Earnings | E1: Sales | F1: EPS | G1: NAVPS | H1: RoE | I1: Normalized P/E | J1: P/B | K1: Dividend Yield | L1: P/E | O1: Sales | R1: Earnings | U1: EPS | X1: DPS | AA1: FY+1
D2: TTM | E2: TTM | F2: TTM - EPS | H2: Avg | L2: FY24E | M2: FY25E | N2: FY26E | O2: FY24E | P2: FY25E | Q2: FY26E | R2: FY24E | S2: FY25E | T2: FY26E | U2: FY24E | V2: FY25E | W2: FY26E | X2: FY24E | Y2: FY25E | Z2: FY26E | AA2: Sales growth | AB2: EPS Growth | AC2: No of Shares
A3: 1 | B3: MGT | C3: 46.9 | D3: =+SUM(MGT!AI26:AL26)/1000 -> 2544.412 | E3: =+SUM(MGT!AI3:AL3)/1000 -> 50252.886 | F3: =+SUM(MGT!AI29:AL29) -> 6.1240039 | G3: =+MGT!AL46 -> 24.110887 | H3: =+MGT!AO33 -> 0.22511269 | I3: =+MGT!AO35 -> 8.0028419 | J3: =+C3/G3 -> 1.9451794 | K3: =+Y3/C3 -> 0.056289979 | L3: =+C3/U3 -> 6.3228851 | M3: =+C3/V3 -> 6.1852951 | N3: =+C3/W3 -> 5.6285629 | O3: =+MGT!AQ11 -> 62655.5 | P3: =+MGT!AV11 -> 55904 | Q3: =+MGT!BA11 -> 62636 | R3: =+MGT!AS11 -> 3075 | S3: =+MGT!AX11 -> 3550 | T3: =+MGT!BC11 -> 3902.5 | U3: =+MGT!AT11 -> 7.4175 | V3: =+MGT!AY11 -> 7.5825 | W3: =+MGT!BD11 -> 8.3325 | X3: =+MGT!AU11 -> 2.575 | Y3: =+MGT!AZ11 -> 2.64 | Z3: =+MGT!BE11 -> 2.84 | AA3: =+P3/O3-1 -> -0.1077559 | AB3: =+S3/R3-1 -> 0.15447154 | AC3: =+MGT!AK44 -> 415481.78
A4: 2 | B4: TJL | C4: 40 | D4: =+SUM(TJL!C24:F24)/1000 -> 1116.479 | E4: =+SUM(TJL!C2:F2)/1000 -> 60698.88 | F4: =+SUM(TJL!C27:F27) -> 1.5577183 | G4: =+TJL!F45 -> 42.011675 | H4: =+TJL!#REF! -> #REF! | I4: =+TJL!#REF! -> #REF! | J4: =+C4/G4 -> 0.95211628 | K4: =+Y4/C4 -> #REF! | L4: =+C4/U4 -> #REF! | M4: =+C4/V4 -> #REF! | N4: =+C4/W4 -> #REF! | O4: =+TJL!#REF! -> #REF! | P4: =+TJL!#REF! -> #REF! | Q4: =+TJL!#REF! -> #REF! | R4: =+TJL!#REF! -> #REF! | S4: =+TJL!#REF! -> #REF! | T4: =+TJL!#REF! -> #REF! | U4: =+TJL!#REF! -> #REF! | V4: =+TJL!#REF! -> #REF! | ... Z4: =+TJL!#REF! -> #REF! | AA4: =+P4/O4-1 -> #REF! | AB4: =+S4/R4-1 -> #REF! | AC4: =+TJL!E43 -> 716739.97
A5: 3 | B5: BPPL | C5: 18.4 | D5: =+SUM(BPPL!AJ26:AM26)/1000 -> 422.00336 | E5: =+SUM(BPPL!AJ3:AM3)/1000 -> 5933.416 | F5: =+SUM(BPPL!AJ29:AM29) -> 1.3753055 | G5: =+BPPL!AM46 -> 13.086935 | H5: =+BPPL!AO33 -> 0.15382125 | I5: =+BPPL!AO35 -> 9.1403653 | J5: =+C5/G5 -> 1.4059824 | AC5: =+BPPL!AK44 -> 306843.36
A6: 4 | B6: HAYL | C6: 95.6 | D6: =+SUM(HAYL!AI28:AL28)/1000 -> 6888.77 | E6: =+SUM(HAYL!AI3:AL3)/1000 -> 436833.27 | F6: =+SUM(HAYL!AI31:AL31) -> 9.1850267 | G6: =+HAYL!AL48 -> 106.88399 | H6: =+HAYL!AN35 -> 0.20139277 | I6: =+HAYL!AN37 -> 4.4412104 | J6: =+C6/G6 -> 0.89442768 | L6: =+C6/U6 -> 10.402612 | M6: =+C6/V6 -> 5.3259053 | O6: =+HAYL!AP11 -> 416563 | P6: =+HAYL!AU11 -> 448372 | R6: =+HAYL!AR11 -> 6892 | S6: =+HAYL!AW11 -> 13460 | U6: =+HAYL!AS11 -> 9.19 | V6: =+HAYL!AX11 -> 17.95 | AA6: =+P6/O6-1 -> 0.076360599 | AB6: =+S6/R6-1 -> 0.95298897 | AC6: =+HAYL!AK46 -> 750000
A7: 5 | B7: HAYC | C7: 79 | D7: =+SUM(HAYC!AI29:AL29)/1000 -> 3743.929 | E7: =+SUM(HAYC!AI3:AL3)/1000 -> 43179.205 | F7: =+SUM(HAYC!AI32:AL32) -> 12.600571 | G7: =+HAYC!AL49 -> 77.089304 | H7: =+HAYC!AN36 -> 0.21881837 | I7: =+HAYC!AN38 -> 4.6832699 | J7: =+C7/G7 -> 1.0247855 | AC7: =+HAYC!AK47 -> 297123.75
A8: 6 | B8: HELA | C8: 5.2 | D8: =+SUM(HELA!AI28:AL28)/1000 -> -1852.217 | E8: =+SUM(HELA!AI3:AL3)/1000 -> 70180.266 | F8: =+SUM(HELA!AI31:AL31) -> -1.4338827 | G8: =+HELA!AL48 -> 6.3843371 | J8: =+C8/G8 -> 0.81449333 | AC8: =+HELA!AK46 -> 1309955.9
A9: 7 | B9: EXPO | C9: 151 | E9: =+SUM(EXPO!AH3:AK3)/1000 -> 239094.62 | F9: =+SUM(EXPO!AH32:AK32) -> -6.9347098 | G9: =+EXPO!AK49 -> 66.043483 | H9: =+EXPO!AO33 -> 0.50793182 | I9: =+EXPO!AO35 -> 4.5013373 | J9: =+C9/G9 -> 2.2863724 | AC9: =+EXPO!AK47 -> 1954915
A10: 8 | B10: GLAS | C10: 27.7 | D10: =+SUM(GLAS!AI26:AL26)/1000 -> 2938.83 | E10: =+SUM(GLAS!AI3:AL3)/1000 -> 17823.509 | F10: =+SUM(GLAS!AI29:AL29) -> 3.093225 | G10: =+GLAS!AL46 -> 11.649883 | H10: =+GLAS!AO33 -> 0.31506446 | I10: =+GLAS!AO35 -> 7.1048548 | J10: =+C10/G10 -> 2.3777062 | K10: =+Y10/C10 -> 0.068592058 | L10: =+C10/U10 -> 9.3581081 | M10: =+C10/V10 -> 7.5271739 | O10: =+GLAS!AQ11 -> 17866 | P10: =+GLAS!AV11 -> 22199 | R10: =+GLAS!AS11 -> 2814 | S10: =+GLAS!AX11 -> 3492 | U10: =+GLAS!AT11 -> 2.96 | V10: =+GLAS!AY11 -> 3.68 | X10: =+GLAS!AU11 -> 1.5 | Y10: =+GLAS!AZ11 -> 1.9 | AA10: =+P10/O10-1 -> 0.24252771 | AB10: =+S10/R10-1 -> 0.24093817 | AC10: =+GLAS!AL44 -> 950086.08
A11: 9 | B11: TKYO | C11: 48.8 | D11: =+SUM(TKYO!AI28:AL28)/1000 -> 2418.725 | E11: =+SUM(TKYO!AI3:AL3)/1000 -> 49823.793 | F11: =+SUM(TKYO!AI31:AL31) -> 5.4840776 | G11: =+TKYO!AL49 -> 62.391858 | H11: =+TKYO!AN35 -> 0.13288721 | I11: =+TKYO!AN37 -> 5.8858436 | J11: =+C11/G11 -> 0.78215334 | K11: =+Y11/C11 -> 0.029713115 | L11: =+C11/U11 -> 4.9317837 | M11: =+C11/V11 -> 6 | O11: =+TKYO!AP11 -> 55247.5 | P11: =+TKYO!AU11 -> 57164.873 | R11: =+TKYO!AR11 -> 4371.5 | S11: =+TKYO!AW11 -> 3581.8067 | U11: =+TKYO!AS11 -> 9.895 | V11: =+TKYO!AX11 -> 8.1333333 | X11: =+TKYO!AT11 -> 1.8 | Y11: =+TKYO!AY11 -> 1.45 | AA11: =+P11/O11-1 -> 0.03470516 | AB11: =+S11/R11-1 -> -0.18064585 | AC11: =+TKYO!AK47 -> 441045
A12: 10 | B12: TILE | C12: 48.9 | D12: =+SUM(TILE!AI28:AL28)/1000 -> 2912.278 | E12: =+SUM(TILE!AI3:AL3)/1000 -> 16131.536 | F12: =+SUM(TILE!AI31:AL31) -> 10.979286 | G12: =+TILE!AL49 -> 56.305925 | H12: =+TILE!AN35 -> 0.21536605 | I12: =+TILE!AN37 -> 4.0325293 | J12: =+C12/G12 -> 0.86846988 | AC12: =+TILE!AK47 -> 265252.05
A13: 11 | B13: JAT | C13: 17.9 | D13: =+SUM(JAT!AI28:AL28)/1000 -> 1021.2017 | E13: =+SUM(JAT!AI3:AL3)/1000 -> 11560.476 | F13: =+SUM(JAT!AI31:AL31) -> 2.0007565 | G13: =+JAT!AL49 -> 17.916 | H13: =+JAT!AN35 -> 0.12066455 | I13: =+JAT!AN37 -> 8.2800373 | J13: =+C13/G13 -> 0.99910697 | AC13: =+JAT!AK47 -> 510407.77
A14: 12 | B14: CARG | C14: 371 | D14: =+SUM(CARG!AI28:AL28)/1000 -> 5886.785 | E14: =+SUM(CARG!AI3:AL3)/1000 -> 223440.48 | F14: =+SUM(CARG!AI31:AL31) -> 22.845533 | G14: =+CARG!AL49 -> 125.86176 | H14: =+CARG!AN35 -> 0.21500723 | I14: =+CARG!AN37 -> 13.709671 | J14: =+C14/G14 -> 2.9476784 | K14: =+Y14/C14 -> 0.039254268 | L14: =+C14/U14 -> 12.079444 | M14: =+C14/V14 -> 8.4812924 | O14: =+CARG!AP11 -> 229901.67 | P14: =+CARG!AU11 -> 264689.33 | R14: =+CARG!AR11 -> 7917 | S14: =+CARG!AW11 -> 11268.333 | U14: =+CARG!AS11 -> 30.713333 | V14: =+CARG!AX11 -> 43.743333 | X14: =+CARG!AT11 -> 10.433333 | Y14: =+CARG!AY11 -> 14.563333 | AA14: =+P14/O14-1 -> 0.15131542 | AB14: =+S14/R14-1 -> 0.42330849 | AC14: =+CARG!AK47 -> 257677.73
A15: 13 | B15: CCS | C15: 55.5 | D15: =+SUM(CCS!AH28:AK28)/1000 -> 3282.209 | E15: =+SUM(CCS!AH3:AK3)/1000 -> 135634.06 | F15: =+SUM(CCS!AH31:AK31) -> 3.4535027 | G15: =+CCS!AK49 -> 21.382158 | H15: =+CCS!AM35 -> 0.15354589 | I15: =+CCS!AM37 -> 16.904535 | J15: =+C15/G15 -> 2.595622 | K15: =+Y15/C15 -> 0.04977942 | L15: =+C15/U15 -> 18.512269 | M15: =+C15/V15 -> 11.302513 | O15: =+CCS!AO11 -> 139919.8 | P15: =+CCS!AT11 -> 155475.6 | R15: =+CCS!AQ11 -> 2848.6 | S15: =+CCS!AV11 -> 4669.2 | U15: =+CCS!AR11 -> 2.9980118 | V15: =+CCS!AW11 -> 4.9104125 | X15: =+CCS!AS11 -> 1.6637574 | Y15: =+CCS!AX11 -> 2.7627578 | AA15: =+P15/O15-1 -> 0.11117655 | AB15: =+S15/R15-1 -> 0.63912097 | AC15: =+CCS!AK47 -> 950400
A16: 14 | B16: LMF | C16: 25.7 | D16: =+SUM(LMF!AI28:AL28)/1000 -> 2273.67 | E16: =+SUM(LMF!AI3:AL3)/1000 -> 16763.349 | F16: =+SUM(LMF!AI31:AL31) -> 5.6844592 | G16: =+LMF!AL49 -> 54.661416 | H16: =+LMF!AN35 -> 0.089831254 | I16: =+LMF!AN37 -> 5.2338923 | J16: =+C16/G16 -> 0.47016711 | AC16: =+LMF!AK47 -> 399980
A17: 15 | B17: LLUB | C17: 121.75 | D17: =+SUM(LLUB!AJ28:AM28)/1000 -> 3832.086 | E17: =+SUM(LLUB!AJ3:AM3)/1000 -> 24063.247 | F17: =+SUM(LLUB!AI31:AL31) -> 14.979983 | G17: =+LLUB!AM49 -> 32.584017 | H17: =+LLUB!AO35 -> 0.60032755 | I17: =+LLUB!AO37 -> 6.2240931 | J17: =+C17/G17 -> 3.7364945 | K17: =+Y17/C17 -> 0.11830801 | M17: =+C17/V17 -> 6.8383509 | N17: =+C17/W17 -> 5.9842713 | P17: =+LLUB!AV9 -> 25710.4 | Q17: =+LLUB!BA9 -> 28683.25 | S17: =+LLUB!AX9 -> 4271.2 | T17: =+LLUB!BC9 -> 4882.5 | V17: =+LLUB!AY9 -> 17.804 | W17: =+LLUB!BD9 -> 20.345 | Y17: =+LLUB!AZ9 -> 14.404 | Z17: =+LLUB!BE9 -> 16.6 | AA17: =+Q17/P17-1 -> 0.11562831 | AB17: =+T17/S17-1 -> 0.14312137 | AC17: =+LLUB!AL47 -> 240000
A18: 16 | B18: LIOC | C18: 114.5 | D18: =+SUM(LIOC!AI28:AL28)/1000 -> 13944.994 | E18: =+SUM(LIOC!AI3:AL3)/1000 -> 263568.72 | F18: =+SUM(LIOC!AH31:AK31) -> 33.242321 | G18: =+LIOC!AL49 -> 137.98101 | H18: =+LIOC!AO35 -> 0.34565378 | I18: =+LIOC!AO37 -> 2.1421055 | J18: =+C18/G18 -> 0.82982432 | K18: =+Y18/C18 -> 0.080393013 | L18: =+C18/U18 -> 3.1544872 | M18: =+C18/V18 -> 2.9081212 | O18: =+LIOC!AQ9 -> 265956.75 | P18: =+LIOC!AV9 -> 304364.5 | R18: =+LIOC!AS9 -> 19320 | S18: =+LIOC!AX9 -> 20953.75 | U18: =+LIOC!AT9 -> 36.2975 | V18: =+LIOC!AY9 -> 39.3725 | X18: =+LIOC!AU9 -> 8.785 | Y18: =+LIOC!AZ9 -> 9.205 | AA18: =+P18/O18-1 -> 0.14441352 | AB18: =+S18/R18-1 -> 0.084562629 | AC18: =+LIOC!AK47 -> 532465.7
A19: 17 | B19: CTC | C19: 1226.25 | D19: =+SUM(CTC!AH32:AK32) -> 25477 | E19: =+SUM(CTC!AH7:AK7) -> 52182 | F19: =+SUM(CTC!AH35:AK35) -> 136.00518 | G19: =+CTC!AK51 -> 53.255393 | H19: =+CTC!AM39 -> 2.1295579 | I19: =+CTC!AM41 -> 10.812496 | J19: =+C19/G19 -> 23.025837 | K19: =+Y19/C19 -> 0.1151315 | M19: =+C19/V19 -> 8.6329796 | P19: =+CTC!AT9 -> 56967.5 | S19: =+CTC!AV9 -> 26606.75 | V19: =+CTC!AW9 -> 142.0425 | Y19: =+CTC!AX9 -> 141.18 | AC19: =+CTC!AK49*1000 -> 187323.75
A20: 18 | B20: DIST | C20: 25.5 | D20: =+SUM(DIST!AH32:AK32)/1000 -> 15115.08 | E20: =+SUM(DIST!AH7:AK7)/1000 -> 49388.349 | F20: =+SUM(DIST!AH35:AK35) -> 3.285887 | G20: =+DIST!AK53 -> 1.9186289 | H20: =+DIST!AM39 -> 1.885936 | I20: =+DIST!AM41 -> 7.0472917 | J20: =+C20/G20 -> 13.290741 | K20: =+Y20/C20 -> 0.10196078 | L20: =+C20/U20 -> 7.6119403 | M20: =+C20/V20 -> 5.9942766 | N20: =+C20/W20 -> 5.704698 | O20: =+DIST!AO11 -> 52966 | P20: =+DIST!AT11 -> 65394.667 | Q20: =+DIST!AY11 -> 71380.5 | R20: =+DIST!AQ11 -> 15381.667 | S20: =+DIST!AV11 -> 19525.333 | T20: =+DIST!BA11 -> 20567.5 | U20: =+DIST!AR11 -> 3.35 | V20: =+DIST!AW11 -> 4.254058 | W20: =+DIST!BB11 -> 4.47 | X20: =+DIST!AS11 -> 2.15 | Y20: =+DIST!AX11 -> 2.6 | Z20: =+DIST!BC11 -> 3.1 | AA20: =+P20/O20-1 -> 0.23465368 | AB20: =+S20/R20-1 -> 0.26938997 | AC20: =+DIST!AK51 -> 4600000
A21: 19 | B21: HHL | C21: 77.9 | D21: =+SUM(HHL!AI28:AL28)/1000 -> 6108.52 | E21: =+SUM(HHL!AI3:AL3)/1000 -> 121613.77 | F21: =+SUM(HHL!AI31:AL31) -> 10.239728 | G21: =+HHL!AL49 -> 72.804785 | H21: =+HHL!AN35 -> 0.1312404 | I21: =+HHL!AN37 -> 8.1528601 | J21: =+C21/G21 -> 1.0699846 | K21: =+Y21/C21 -> 0.049743261 | L21: =+C21/U21 -> 7.5338491 | M21: =+C21/V21 -> 5.8553818 | O21: =+HHL!AP11 -> 124057.4 | P21: =+HHL!AU11 -> 140094.4 | R21: =+HHL!AR11 -> 6204.4 | S21: =+HHL!AW11 -> 7975.6 | U21: =+HHL!AS11 -> 10.34 | V21: =+HHL!AX11 -> 13.304 | X21: =+HHL!AT11 -> 2.95 | Y21: =+HHL!AY11 -> 3.875 | AA21: =+P21/O21-1 -> 0.12927081 | AB21: =+S21/R21-1 -> 0.28547482 | AC21: =+HHL!AK47 -> 596551.03
A22: 20 | B22: SUN | C22: 58.1 | D22: =+SUM(SUN!AH28:AK28)/1000 -> 4019.7229 | E22: =+SUM(SUN!AH3:AK3)/1000 -> 55711.077 | F22: =+SUM(SUN!AH31:AK31) -> 8.1706065 | G22: =+SUN!AK49 -> 37.156922 | H22: =+SUN!AM35 -> 0.19809302 | I22: =+SUN!AM37 -> 7.8934565 | J22: =+C22/G22 -> 1.5636386 | K22: =+Y22/C22 -> 0.050344234 | L22: =+C22/U22 -> 5.7906977 | M22: =+C22/V22 -> 5.1129363 | O22: =+SUN!AO11 -> 57142.333 | P22: =+SUN!AT11 -> 65798 | R22: =+SUN!AQ11 -> 4939 | S22: =+SUN!AV11 -> 5595.6667 | U22: =+SUN!AR11 -> 10.033333 | V22: =+SUN!AW11 -> 11.363333 | X22: =+SUN!AS11 -> 2.25 | Y22: =+SUN!AX11 -> 2.925 | AA22: =+P22/O22-1 -> 0.15147556 | AB22: =+S22/R22-1 -> 0.13295539 | AC22: =+SUN!AK47 -> 491973.63
A23: 21 | B23: DIAL | C23: 9.4 | D23: =+SUM(DIAL!AJ28:AM28)/1000 -> 14190.296 | E23: =+SUM(DIAL!AJ3:AM3)/1000 -> 180914.26 | F23: =+SUM(DIAL!AI31:AL31) -> 2.4386197 | G23: =+DIAL!AL49 -> 8.0431202 | H23: =+DIAL!AO35 -> -0.078553248 | J23: =+C23/G23 -> 1.1687007 | K23: =+Y23/C23 -> 0.069680851 | L23: =+C23/U23 -> 4 | M23: =+C23/V23 -> 7.43083 | N23: =+C23/W23 -> 4.4976077 | O23: =+DIAL!AQ11 -> 192901 | P23: =+DIAL!AV11 -> 180360.5 | Q23: =+DIAL!BA11 -> 194372.5 | R23: =+DIAL!AS11 -> 19373 | S23: =+DIAL!AX11 -> 10827 | T23: =+DIAL!BC11 -> 18197.5 | U23: =+DIAL!AT11 -> 2.35 | V23: =+DIAL!AY11 -> 1.265 | W23: =+DIAL!BD11 -> 2.09 | X23: =+DIAL!AU11 -> 0.94 | Y23: =+DIAL!AZ11 -> 0.655 | Z23: =+DIAL!BE11 -> 1.045 | AA23: =+P23/O23-1 -> -0.065010031 | AB23: =+S23/R23-1 -> -0.44112941 | AC23: =+DIAL!AL47 -> 8247640.3
A24: 22 | B24: PLR | C24: 7.6 | D24: =+SUM(PLR!AI29:AL29)/1000 -> 1129.0017 | E24: =+SUM(PLR!AI3:AL3)/1000 -> 8090.3791 | F24: =+SUM(PLR!AI32:AL32) -> 1.2042685 | G24: =+PLR!AL49 -> 10.213058 | H24: =+PLR!AN36 -> 0.27339238 | I24: =+PLR!AN38 -> 2.7218952 | J24: =+C24/G24 -> 0.74414542 | AC24: =+PLR!AK47 -> 937500
A25: 23 | B25: SAMP | C25: 73.8
A26: 24 | B26: NTB | C26: 120
A27: 25 | B27: HNB | C27: 181.5
A28: 26 | B28: COMB | C28: 89
A29: 27 | B29: PABC | C29: 19.8
A30: 28 | B30: SEYB | C30: 43.6
A31: 29 | B31: AAIC | C31: 64.5 | D31: =+SUM(AAIC!AJ48:AM48)/1000 -> 3190.381 | E31: =+SUM(AAIC!AJ16:AM16)/1000 -> 32959.621 | F31: =+SUM(AAIC!AI51:AL51) -> 7.5690773 | G31: =+AAIC!AL83 -> 35.555589 | H31: =+AAIC!AO55 -> 0.2458523 | I31: =+AAIC!AO57 -> 7.7061726 | J31: =+C31/G31 -> 1.8140608 | AC31: =+AAIC!AM81 -> 375000
A32: 30 | B32: KHL | C32: 15.6
A33: 31 | B33: AHUN | C33: 63.6
A34: 32 | B34: WATA | C34: 85.5 | D34: =+SUM(WATA!AI28:AL28)/1000 -> 2358.77 | E34: =+SUM(WATA!AI3:AL3)/1000 -> 8320.903 | F34: =+SUM(WATA!AH31:AK31) -> 9.6700123 | G34: =+WATA!AK49 -> 29.72584 | H34: =+WATA!AN35 -> 0.37047571 | I34: =+WATA!AN37 -> 7.581621 | J34: =+C34/G34 -> 2.8762854 | AC34: =+WATA!AK47 -> 203308.63
A35: 33 | B35: ACL | C35: 82.5
A36: 34 | B36: PACK | C36: 13.2
A37: 35 | B37: ASIR | C37: 23.8
A38: 36 | B38: DIPD | C38: 33.5
A39: 37 | B39: JKH | C39: 177.75
A40: 38 | B40: AEL | C40: 21
...

Sheet MGT
W1: Stock Price | X1: =+'Valuation Sheet'!C3 -> 46.9
B2: MGT - Rs mn | C2: FY16 | D2: FY17 | E2: FY18 | F2: FY19 | G2: FY20 | H2: FY21 | I2: FY22 | J2: CAGR/AVG | M2: MPS | N2: ='[1]LT Portfolio'!I294 -> SELL | P2: AVG | Q2: =J14*J21 -> 21.034273 | W2: MGT | X2: 2Q21 | Y2: 3Q21 | Z2: 4Q21 | AA2: 1Q22 | AB2: 2Q22 | AC2: 3Q22 | AD2: 4Q22 | AE2: 1Q23 | AF2: 2Q23 | AG2: 3Q23 | AH2: 4Q23 | AI2: 1Q24 | AJ2: 2Q24 | AK2: 3Q24 | AL2: 4Q24 | AM2: 1Q25 | AP2: =+W2 -> MGT | AQ2: FY24E | AV2: FY25E | BA2: FY26E
B3: Net Revenue | C3: 8494.841 | D3: 8332.832 | E3: 8964.529 | F3: 11982.988 | G3: 12225.353 | H3: 14769.114 | I3: 31652.58 | M3: P/E | N3: ='[1]LT Portfolio'!W294 -> 0 | W3: Revenue (LKR 000) | X3: 4205828 | Y3: 3844988 | Z3: 3723204 | AA3: 5813709 | AB3: 8155862 | AC3: 8490686 | AD3: 9200419 | AE3: 15038517 | AF3: 16795679 | AG3: 14956175 | AH3: 14158418 | AI3: 14276671 | AJ3: 15877062 | AK3: 10686568 | AL3: 9412585 | AM3: 12912687 | AQ3: Revenue | AR3: EBIT | AS3: NP | AT3: EPS | AU3: DPS | AV3: Revenue | AW3: EBIT | AX3: NP | AY3: EPS | AZ3: DPS | BA3: Revenue | BB3: EBIT | BC3: NP | BD3: EPS | BE3: DPS
B4: Revenue Growth | D4: =(D3/C3-1)*100 -> -1.9071458 | E4: =(E3/D3-1)*100 -> 7.5808201 | F4: =(F3/E3-1)*100 -> 33.671139 | G4: =(G3/F3-1)*100 -> 2.0225757 | H4: =(H3/G3-1)*100 -> 20.80726 | I4: =(I3/H3-1)*100 -> 114.31604 | J4: =((I3/D3)^(1/5)-1)*100 -> 30.594022 | W4: YoY% | AB4: =+AB3/X3-1 -> 0.93918106 | AC4: =+AC3/Y3-1 -> 1.2082477 | AD4: =+AD3/Z3-1 -> 1.4711026 | AE4: =+AE3/AA3-1 -> 1.5867337 | AF4: =+AF3/AB3-1 -> 1.0593383 | AG4: =+AG3/AC3-1 -> 0.76148017 | AH4: =+AH3/AD3-1 -> 0.53888839 | AI4: =+AI3/AE3-1 -> -0.050659649 | ... AM4: =+AM3/AI3-1 -> -0.095539359 | AP4: CT CLSA
B5: Gross Profit | C5: 1070.806 | D5: 974.244 | E5: 944.457 | F5: 1428.694 | G5: 1584.661 | H5: 2019.458 | I5: 4121.563 | M5: 2Q21 | N5: =202.575/415.481776 -> 0.48756651 | W5: QoQ% | Y5: =+Y3/X3-1 -> -0.085795235 | Z5: =+Z3/Y3-1 -> -0.031673441 | AA5: =+AA3/Z3-1 -> 0.56148011 | AB5: =+AB3/AA3-1 -> 0.40286726 | AC5: =+AC3/AB3-1 -> 0.041053171 | AD5: =+AD3/AC3-1 -> 0.083589595 | AE5: =+AE3/AD3-1 -> 0.63454697 | AF5: =+AF3/AE3-1 -> 0.1168441 | ... AM5: =+AM3/AL3-1 -> 0.37185343 | AP5: Capital Alliance | AY5: 7.64 | AZ5: 3.06 | BD5: 8.41 | BE5: 3.36
B6: GPM | C6: =C5/C$3*100 -> 12.605368 | D6: =D5/D$3*100 -> 11.691631 | E6: =E5/E$3*100 -> 10.535489 | F6: =F5/F$3*100 -> 11.922686 | G6: =G5/G$3*100 -> 12.962088 | H6: =H5/H$3*100 -> 13.673522 | I6: =I5/I$3*100 -> 13.021255 | J6: =AVERAGE(D6:I6) -> 12.301112 | M6: 3Q21 | N6: =261.001/415.481776 -> 0.6281888 | AP6: Asia Securities | AQ6: 66126 | AR6: 6855 | AS6: 3815 | AT6: 9.18 | AU6: 2.75
B7: EBIT | C7: =+C9--118.373 -> 375.379 | D7: =+D9--140.04 -> 202.055 | E7: =+E9--151.365 -> 143.743 | F7: =+F9--152.896 -> 469.664 | G7: =+G9--145.801 -> 449.796 | H7: =+H9--159.323 -> 889.898 | I7: =+I9-1399.847 -> 1755.797 | M7: 4Q21 | N7: ='[1]LT Portfolio'!P294 -> 0 | W7: Revenue (in USD) | X7: 22386114 | Y7: 20462583 | Z7: 18813703 | AA7: 28796894 | AB7: 40189860 | AC7: 41826038 | AD7: 39405896 | AE7: 41283608 | AF7: 45535349 | AG7: 40229056 | AH7: 39583449 | AI7: 45114143 | AJ7: 47978792 | AK7: 31973060 | AL7: 30260825 | AM7: 42207980 | AP7: First Capital | AQ7: 65198 | AR7: 5724 | AS7: 3356 | AT7: 8.1 | AU7: 2.4 | AV7: 57931 | AW7: 6428 | AX7: 4095 | AY7: 9.9 | AZ7: 3 | BA7: 66531 | BB7: 7036 | BC7: 4744 | BD7: 11.4 | BE7: 3.4
B8: EBIT Margin | C8: =C7/C$3*100 -> 4.4189055 | D8: =D7/D$3*100 -> 2.4248059 | E8: =E7/E$3*100 -> 1.6034641 | F8: =F7/F$3*100 -> 3.9194231 | G8: =G7/G$3*100 -> 3.6792066 | H8: =H7/H$3*100 -> 6.0253987 | I8: =I7/I$3*100 -> 5.5470897 | J8: =AVERAGE(D8:I8) -> 3.8665647 | M8: 1Q22 | N8: ='[1]LT Portfolio'!Q294 -> 0 | W8: YoY% | AB8: =+AB7/X7-1 -> 0.79530311 | AC8: =+AC7/Y7-1 -> 1.0440253 | AD8: =+AD7/Z7-1 -> 1.0945316 | AE8: =+AE7/AA7-1 -> 0.43361322 | AF8: =+AF7/AB7-1 -> 0.13300591 | AG8: =+AG7/AC7-1 -> -0.038181527 | AH8: =+AH7/AD7-1 -> 0.0045057471 | AI8: =+AI7/AE7-1 -> 0.092785858 | ... AM8: =+AM7/AI7-1 -> -0.064418003 | AP8: Acuity Research | AY8: 5.56 | AZ8: 2 | BD8: 6.15 | BE8: 2
B9: PBT | C9: 257.006 | D9: 62.015 | E9: -7.622 | F9: 316.768 | G9: 303.995 | H9: 730.575 | I9: 3155.644 | M9: 2Q22 | N9: ='[1]LT Portfolio'!R294 -> 0 | O9: =N9/N5-1 -> -1 | W9: QoQ% | Y9: =+Y7/X7-1 -> -0.085925186 | Z9: =+Z7/Y7-1 -> -0.080580247 | AA9: =+AA7/Z7-1 -> 0.53063403 | AB9: =+AB7/AA7-1 -> 0.39563177 | AC9: =+AC7/AB7-1 -> 0.040711214 | AD9: =+AD7/AC7-1 -> -0.057862091 | AE9: =+AE7/AD7-1 -> 0.047650534 | AF9: =+AF7/AE7-1 -> 0.1029886 | ... AM9: =+AM7/AL7-1 -> 0.39480599 | AP9: Asia Capital | AQ9: 61649 | AR9: 4200 | AS9: 2600 | AT9: 6.3
B10: Net Profit | C10: 261.605 | D10: 73.56 | E10: -105.597 | F10: 181.325 | G10: 231.445 | H10: 736.239 | I10: 2692.346 | J10: =((I10/D10)^(1/5)-1)*100 -> 105.44607 | M10: 3Q22 | N10: ='[1]LT Portfolio'!S294 -> 0 | O10: =N10/N6-1 -> -1 | AP10: JKSB | AQ10: 57649 | AR10: 4507 | AS10: 2529 | AT10: 6.09 | AV10: 53877 | AW10: 5164 | AX10: 3005 | AY10: 7.23 | AZ10: 2.5 | BA10: 58741 | BB10: 5618 | BC10: 3061 | BD10: 7.37 | BE10: 2.6
B11: NP Margin | C11: =C10/C$3*100 -> 3.079575 | D11: =D10/D$3*100 -> 0.88277311 | E11: =E10/E$3*100 -> -1.1779425 | F11: =F10/F$3*100 -> 1.5131869 | G11: =G10/G$3*100 -> 1.893156 | H11: =H10/H$3*100 -> 4.984991 | I11: =I10/I$3*100 -> 8.5059291 | J11: =AVERAGE(D11:I11) -> 2.7670156 | M11: 4Q22 | N11: ='[1]LT Portfolio'!T294 -> 0 | O11: =N11/N7-1 -> #DIV/0! | W11: Gross Profit | X11: 536176 | Y11: 543061 | Z11: 494974 | AA11: 830348 | AB11: 990442 | AC11: 1131305 | AD11: 1170194 | AE11: 1947604 | AF11: 1795972 | AG11: 2012466 | AH11: 2069956 | AI11: 2759012 | AJ11: 2792611 | AK11: 1967739 | AL11: 1920313 | AM11: 2536969 | AP11: Consensus | AQ11: =+AVERAGE(AQ4:AQ10) -> 62655.5 | AR11: =+AVERAGE(AR4:AR10) -> 5321.5 | AS11: =+AVERAGE(AS4:AS10) -> 3075 | AT11: =+AVERAGE(AT4:AT10) -> 7.4175 | AU11: =+AVERAGE(AU4:AU10) -> 2.575 | AV11: =+AVERAGE(AV4:AV10) -> 55904 | AW11: =+AVERAGE(AW4:AW10) -> 5796 | AX11: =+AVERAGE(AX4:AX10) -> 3550 | ... BE11: =+AVERAGE(BE4:BE10) -> 2.84
B12: NP Growth | D12: =(D10/C10-1)*100 -> -71.881271 | E12: =(E10/D10-1)*100 -> -243.5522 | F12: =-(F10/E10-1)*100 -> 271.71416 | G12: =(G10/F10-1)*100 -> 27.640976 | H12: =(H10/G10-1)*100 -> 218.10538 | I12: =(I10/H10-1)*100 -> 265.68913 | J12: =AVERAGE(D12:I12) -> 77.952696 | S12: 1Q22 | T12: 2Q22 | W12: GPM% | X12: =+X11/X3 -> 0.12748405 | Y12: =+Y11/Y3 -> 0.14123867 | Z12: =+Z11/Z3 -> 0.13294302 | AA12: =+AA11/AA3 -> 0.14282586 | AB12: =+AB11/AB3 -> 0.12143928 | AC12: =+AC11/AC3 -> 0.13324071 | AD12: =+AD11/AD3 -> 0.12718921 | AE12: =+AE11/AE3 -> 0.12950772 | ... AM12: =+AM11/AM3 -> 0.19647104 | AU12: DY | AZ12: DY | BE12: DY
M13: TTM | N13: =SUM(N8:N11) -> 0 | Q13: =N13*J21 -> 0 | S13: 19.109574 | T13: 18.873653 | AP13: Leading P/E | AT13: =+$X$1/AT11 -> 6.3228851 | AU13: =+AU11/$X$1 -> 0.054904051 | AY13: =+$X$1/AY11 -> 6.1852951 | AZ13: =+AZ11/$X$1 -> 0.056289979 | BD13: =+$X$1/BD11 -> 5.6285629 | BE13: =+BE11/$X$1 -> 0.060554371
B14: EPS | C14: =1.26/2 -> 0.63 | D14: =0.35/2 -> 0.175 | E14: =-0.51/2 -> -0.255 | F14: =0.87/2 -> 0.435 | G14: 0.56 | H14: 1.77 | I14: 6.48 | J14: =AVERAGE(D14:I14) -> 1.5275 | M14: P/E | N14: =N2/N13 -> #VALUE! | Q14: =Q13/N2-1 -> #VALUE! | S14: =S13/N2-1 -> #VALUE! | T14: =T13/N2-1 -> #VALUE! | W14: EBIT | X14: =+X20-X17 -> 288324 | Y14: =+Y20-Y17 -> 273890 | Z14: =+Z20-Z17 -> 144579 | AA14: =+AA20-AA17 -> 339439 | AB14: =+AB20-AB17 -> 536419 | AC14: =+AC20-AC17 -> 576435 | AD14: =+AD20-AD17 -> 304232 | AE14: =+AE20-AE17 -> 1018801 | ... AM14: =+AM20-AM17 -> 1355526
B15: DPS | C15: 0 | D15: 0 | E15: 0 | F15: 0 | G15: 0.3 | H15: 0.7 | I15: 2.1 | W15: EBIT margin % | X15: =+X14/X3 -> 0.068553445 | Y15: =+Y14/Y3 -> 0.071232992 | Z15: =+Z14/Z3 -> 0.038831877 | AA15: =+AA14/AA3 -> 0.058385963 | AB15: =+AB14/AB3 -> 0.065770976 | AC15: =+AC14/AC3 -> 0.067890274 | AD15: =+AD14/AD3 -> 0.03306719 | AE15: =+AE14/AE3 -> 0.067746108 | ... AM15: =+AM14/AM3 -> 0.10497629
B16: MPS | C16: 9 | D16: =13.6/2 -> 6.8 | E16: =12.5/2 -> 6.25 | F16: =8.5/2 -> 4.25 | G16: =8.7/2 -> 4.35 | H16: 14.1 | I16: 29.1 | J16: =((I16/D16)^(1/5)-1)*100 -> 33.744772
B17: BVPS | C17: =2578.373/415.481776 -> 6.2057427 | D17: =2707.107/415.481776 -> 6.5155854 | E17: =2683.152/415.481776 -> 6.4579295 | F17: =3179.299/415.481776 -> 7.6520781 | G17: =3543.165/415.481776 -> 8.527847 | H17: =4225.563/415.481776 -> 10.170273 | I17: =9106.62/415.481776 -> 21.918218 | J17: =((I17/D17)^(1/6)-1)*100 -> 22.40767 | W17: Net Finance Income/Cost | X17: -54287 | Y17: -38665 | Z17: 2948 | AA17: -36232 | AB17: -90483 | AC17: -148715 | AD17: 1674940 | AE17: 986461 | AF17: -412419 | AG17: -536441 | AH17: -1170365 | AI17: -828137 | AJ17: -203592 | AK17: -271856 | AL17: -675330 | AM17: -192506
B18: ROE | C18: =C14/AVERAGE(B17:C17)*100 -> 10.151887 | D18: =D14/AVERAGE(C17:D17)*100 -> 2.7512851 | E18: =E14/AVERAGE(D17:E17)*100 -> -3.9310858 | F18: =F14/AVERAGE(E17:F17)*100 -> 6.1658365 | G18: =G14/AVERAGE(F17:G17)*100 -> 6.9221581 | H18: =H14/AVERAGE(G17:H17)*100 -> 18.932385 | I18: =I14/AVERAGE(H17:I17)*100 -> 40.388313 | J18: =AVERAGE(D18:I18) -> 11.871482 | M18: MGT | W18: As a % of EBIT | X18: =+X17/X14 -> -0.18828471 | Y18: =+Y17/Y14 -> -0.14116981 | Z18: =+Z17/Z14 -> 0.020390236 | AA18: =+AA17/AA14 -> -0.10674083 | AB18: =+AB17/AB14 -> -0.16867971 | AC18: =+AC17/AC14 -> -0.25799093 | AD18: =+AD17/AD14 -> 5.5054695 | AE18: =+AE17/AE14 -> 0.9682568 | ... AM18: =+AM17/AM14 -> -0.14201572
B19: DY | C19: =C15/C16*100 -> 0 | D19: =D15/D16*100 -> 0 | E19: =E15/E16*100 -> 0 | F19: =F15/F16*100 -> 0 | G19: =G15/G16*100 -> 6.8965517 | H19: =H15/H16*100 -> 4.964539 | I19: =I15/I16*100 -> 7.2164948 | J19: =AVERAGE(G19:I19) -> 6.3591952
B20: Dividend Payout | C20: =C15/C14*100 -> 0 | D20: =D15/D14*100 -> 0 | E20: =E15/E14*100 -> 0 | F20: =F15/F14*100 -> 0 | G20: =G15/G14*100 -> 53.571429 | H20: =H15/H14*100 -> 39.548023 | I20: =I15/I14*100 -> 32.407407 | J20: =AVERAGE(G20:I20) -> 41.842286 | M20: YoY Growth | N20: =N13/H14-1 -> -1 | W20: PBT | X20: 234037 | Y20: 235225 | Z20: 147527 | AA20: 303207 | AB20: 445936 | AC20: 427720 | AD20: 1979172 | AE20: 2005262 | AF20: 535611 | AG20: 505819 | AH20: 19443 | AI20: 1062325 | AJ20: 1464266 | AK20: 826887 | AL20: 447230 | AM20: 1163020
B21: P/E | C21: =C16/C14 -> 14.285714 | D21: =D16/D14 -> 38.857143 | E21: N/A | F21: =F16/F14 -> 9.7701149 | G21: =G16/G14 -> 7.7678571 | H21: =H16/H14 -> 7.9661017 | I21: =I16/I14 -> 4.4907407 | J21: =AVERAGE(D21:I21) -> 13.770391 | W21: PBT Margin% | X21: =+X20/X3 -> 0.05564588 | Y21: =+Y20/Y3 -> 0.061177044 | Z21: =+Z20/Z3 -> 0.039623668 | AA21: =+AA20/AA3 -> 0.052153797 | AB21: =+AB20/AB3 -> 0.054676747 | AC21: =+AC20/AC3 -> 0.050375199 | AD21: =+AD20/AD3 -> 0.21511759 | AE21: =+AE20/AE3 -> 0.13334174 | ... AM21: =+AM20/AM3 -> 0.090068008
B22: P/B | C22: =C16/C17 -> 1.4502696 | D22: =D16/D17 -> 1.0436514 | E22: =E16/E17 -> 0.96780246 | F22: =F16/F17 -> 0.55540468 | G22: =G16/G17 -> 0.51009358 | H22: =H16/H17 -> 1.3863935 | I22: =I16/I17 -> 1.3276627 | J22: =AVERAGE(D22:I22) -> 0.96516806
W23: Taxes | X23: -31462 | Y23: 25776 | Z23: 19850 | AA23: -3025 | AB23: -52092 | AC23: -30616 | AD23: -377685 | AE23: -394976 | AF23: -34224 | AG23: -2257323 | AH23: 34825 | AI23: -160723 | AJ23: -533986 | AK23: -275218 | AL23: -286369 | AM23: -374214
W24: ETR% | X24: =+X23/X20 -> -0.13443174 | Y24: =+Y23/Y20 -> 0.10958019 | Z24: =+Z23/Z20 -> 0.13455164 | AA24: =+AA23/AA20 -> -0.0099766826 | AB24: =+AB23/AB20 -> -0.11681497 | AC24: =+AC23/AC20 -> -0.071579538 | AD24: =+AD23/AD20 -> -0.1908298 | AE24: =+AE23/AE20 -> -0.19696977 | ... AM24: =+AM23/AM20 -> -0.32176059
W26: Net Profit Attributable to Equity Holders | X26: =+X20+X23 -> 202575 | Y26: =+Y20+Y23 -> 261001 | Z26: =+Z20+Z23 -> 167377 | AA26: 298809 | AB26: =+AB20+AB23 -> 393844 | AC26: =+AC20+AC23 -> 397104 | AD26: =+AD20+AD23 -> 1601487 | AE26: =+AE20+AE23 -> 1610286 | AF26: =+AF20+AF23 -> 501387 | AG26: =+AG20+AG23 -> -1751504 | AH26: =+AH20+AH23 -> 54268 | AI26: =+AI20+AI23 -> 901602 | ... AM26: =+AM20+AM23 -> 788806
W27: NP Margin | X27: =+X26/X3 -> 0.048165308 | Y27: =+Y26/Y3 -> 0.067880836 | Z27: =+Z26/Z3 -> 0.044955098 | AA27: =+AA26/AA3 -> 0.051397309 | AB27: =+AB26/AB3 -> 0.048289684 | AC27: =+AC26/AC3 -> 0.046769366 | AD27: =+AD26/AD3 -> 0.17406675 | AE27: =+AE26/AE3 -> 0.10707745 | ... AM27: =+AM26/AM3 -> 0.061087673
W29: EPS | X29: =+X26/X44 -> 0.48756651 | Y29: =+Y26/Y44 -> 0.6281888 | Z29: =+Z26/Z44 -> 0.4028504 | AA29: =+AA26/AA44 -> 0.71918678 | AB29: =+AB26/AB44 -> 0.94792124 | AC29: =+AC26/AC44 -> 0.95576755 | AD29: =+AD26/AD44 -> 3.8545301 | AE29: =+AE26/AE44 -> 3.8757079 | ... AM29: =+AM26/AM44 -> 1.8985333
W30: YoY% | AB30: =+AB29/X29-1 -> 0.94418857 | AC30: =+AC29/Y29-1 -> 0.52146543 | AD30: =+AD29/Z29-1 -> 8.5681426 | AE30: =+AE29/AA29-1 -> 4.3890144 | AF30: =+AF29/AB29-1 -> 0.27305989 | AG30: =+AG29/AC29-1 -> -5.4106934 | AH30: =+AH29/AD29-1 -> -0.96611399 | AI30: =+AI29/AE29-1 -> -0.44009822 | ... AM30: =+AM29/AI29-1 -> -0.1251062
W31: QoQ% | Y31: =+Y29/X29-1 -> 0.28841664 | Z31: =+Z29/Y29-1 -> -0.35871127 | AA31: =+AA29/Z29-1 -> 0.78524528 | AB31: =+AB29/AA29-1 -> 0.31804598 | AC31: =+AC29/AB29-1 -> 0.008277389 | AD31: =+AD29/AC29-1 -> 3.0329158 | AE31: =+AE29/AD29-1 -> 0.0054942688 | AF31: =+AF29/AE29-1 -> -0.68863481 | ... AM31: =+AM29/AL29-1 -> 3.9036497
W33: RoE | X33: =+X26*4/X38 -> 0.21880325 | Y33: =+Y26*4/Y38 -> 0.26608611 | Z33: =+Z26*4/Z38 -> 0.15844232 | AA33: =+AA26*4/AA38 -> 0.26417908 | AB33: =+AB26*4/AB38 -> 0.33463886 | AC33: =+AC26*4/AC38 -> 0.32163279 | AD33: =+AD26*4/AD38 -> 0.70343852 | AE33: =+AE26*4/AE38 -> 0.52541963 | ... AM33: =+AM26*4/AM38 -> 0.29170884 | AO33: =+AVERAGE(X33:AM33) -> 0.22511269 | AP33: RoE
AO34: =AVERAGE(X33:AM33)*AM46 -> 5.8604182 | AP34: Normalized EPS
W35: Debt | X35: =458156+20243+117220+2518992+120544+73430 -> 3308585 | Y35: =427579+20515+37702+2071957+130492+259+14173 -> 2702677 | Z35: =665230+21442+2450325+206964+1710+14513 -> 3360184 | AA35: =2475789+50187+410550+5199370+645148+5694+16681 -> 8803419 | AB35: =3184597+52828+347748+6048749+838725+5749+109192 -> 10587588 | AC35: =3263109+50583+228179+5751721+980500+6110+112463 -> 10392665 | AD35: =5159752+56481+451023+5743337+1483655+6307+101485 -> 13002040 | AE35: =5547633+65114+838008+7402911+1636129+7291+270345 -> 15767431 | AF35: =6224823+778972+5252626+1764488+8021+35415+66326 -> 14130671 | AG35: =5846288+63700+698790+7061420+1778365+8575+78300 -> 15535438 | AH35: =5268880+54205+1115814+6252914+1709815+7132+24957 -> 14433717 | AI35: =5350879+52804+564162+4618204+1979211+7691+45958 -> 12618909 | AJ35: =4984053+54870+77686+4156073+2308739+8421+400393 -> 11990235 | AK35: =5737074+51732+174112+2783377+2848164+9081+142756 -> 11746296 | AL35: =5172466+43558+616901+3103581+2775437+7899+81127 -> 11800969 | AM35: =4692694+45982+728005+3988047+2860326+7168+173065 -> 12495287 | AO35: =X1/AO34 -> 8.0028419 | AP35: P/E
W36: Cash | X36: 291769 | Y36: 645466 | Z36: 646002 | AA36: 1002776 | AB36: 1909683 | AC36: 1877694 | AD36: 2952809 | AE36: 2662859 | AF36: 2098362 | AG36: 1776260 | AH36: 1529726 | AI36: 2811177 | AJ36: 4040619 | AK36: 3756291 | AL36: 3371785 | AM36: 3971423
W37: Net Debt | X37: =+X35-X36 -> 3016816 | Y37: =+Y35-Y36 -> 2057211 | Z37: =+Z35-Z36 -> 2714182 | AA37: =+AA35-AA36 -> 7800643 | AB37: =+AB35-AB36 -> 8677905 | AC37: =+AC35-AC36 -> 8514971 | AD37: =+AD35-AD36 -> 10049231 | AE37: =+AE35-AE36 -> 13104572 | ... AM37: =+AM35-AM36 -> 8523864
W38: Equity | X38: 3703327 | Y38: 3923557 | Z38: 4225563 | AA38: 4524340 | AB38: 4707690 | AC38: 4938601 | AD38: 9106621 | AE38: 12259047 | AF38: 12433522 | AG38: 10587154 | AH38: 9491660 | AI38: 9822005 | AJ38: 10397293 | AK38: 10726162 | AL38: 10017634 | AM38: 10816347
W40: Debt/Equity | X40: =+X35/X38 -> 0.89340882 | Y40: =+Y35/Y38 -> 0.68883337 | Z40: =+Z35/Z38 -> 0.79520386 | AA40: =+AA35/AA38 -> 1.9457908 | AB40: =+AB35/AB38 -> 2.2489986 | AC40: =+AC35/AC38 -> 2.1043743 | AD40: =+AD35/AD38 -> 1.4277568 | AE40: =+AE35/AE38 -> 1.2861873 | ... AM40: =+AM35/AM38 -> 1.1552225
W42: Average Exchange rate (income Statement) | X42: =+(X3*1000)/X7 -> 187.87665 | Y42: =+(Y3*1000)/Y7 -> 187.90336 | Z42: =+(Z3*1000)/Z7 -> 197.89852 | AA42: =+(AA3*1000)/AA7 -> 201.88667 | AB42: =+(AB3*1000)/AB7 -> 202.93333 | AC42: =+(AC3*1000)/AC7 -> 203.00001 | AD42: =+(AD3*1000)/AD7 -> 233.47823 | AE42: =+(AE3*1000)/AE7 -> 364.27332 | ... AM42: =+(AM3*1000)/AM7 -> 305.92999
W44: Number of shares | X44: 415481.78 | Y44: 415481.78 | Z44: 415481.78 | AA44: 415481.78 | AB44: 415481.78 | AC44: 415481.78 | AD44: 415481.78 | AE44: 415481.78 | AF44: 415481.78 | AG44: 415481.78 | AH44: 415481.78 | AI44: 415481.78 | AJ44: 415481.78 | AK44: 415481.78 | AL44: 415481.78 | AM44: 415481.78
W46: Net Asset Value per share | X46: =+X38/X44 -> 8.913332 | Y46: =+Y38/Y44 -> 9.4433913 | Z46: =+Z38/Z44 -> 10.170273 | AA46: =+AA38/AA44 -> 10.889383 | AB46: =+AB38/AB44 -> 11.330677 | AC46: =+AC38/AC44 -> 11.886444 | AD46: =+AD38/AD44 -> 21.91822 | AE46: =+AE38/AE44 -> 29.505619 | ... AM46: =+AM38/AM44 -> 26.033265
W48: Cashflow from operations (in USD) | Y48: =+Y52-X52 -> 8266883 | Z48: =+Z52-Y52 -> -599282 | AA48: =+AA52 -> -2082902 | AB48: =+AB52-AA52 -> -639658 | AC48: =+AC52-AB52 -> 2935745 | AD48: =+AD52-AC52 -> 6978985 | AE48: =+AE52 -> -1748438 | AF48: =+AF52-AE52 -> 5876196 | AG48: =+AG52-AF52 -> -4033069 | AH48: =+AH52-AG52 -> 1241217 | AI48: =+AI52 -> 9026075 | AJ48: =+AJ52-AI52 -> 8257139 | AK48: =+AK52-AJ52 -> 2183018 | AL48: =+AL52-AK52 -> -475189 | AM48: =+AM52 -> 2025071
...

Sheet TJL
A1: TJL | B1: 4Q23 | C1: 1Q24 | D1: 2Q24 | E1: 3Q24 | F1: 4Q24 | G1: 1Q25 | H1: 2Q25
A2: Revenue (LKR 000) | B2: 17301185 | C2: 13997150 | D2: 15549880 | E2: 15897519 | F2: 15254331 | G2: 15392521 | H2: 17280011
A3: YoY% | F3: =(F2-B2)/B2 -> -0.11830716 | G3: =(G2-C2)/C2 -> 0.099689651 | H3: =(H2-D2)/D2 -> 0.1112633
A4: QoQ% | C4: =+C2/B2-1 -> -0.1909716 | D4: =+D2/C2-1 -> 0.11093187 | E4: =+E2/D2-1 -> 0.022356378 | F4: =+F2/E2-1 -> -0.040458389 | G4: =+G2/F2-1 -> 0.0090590666 | H4: =+H2/G2-1 -> 0.12262384
A6: COGS | C6: =C2-C9 -> 13714016 | D6: =D2-D9 -> 13658699 | E6: =E2-E9 -> 14615257 | F6: =F2-F9 -> 13752961 | G6: =G2-G9 -> 14098757 | H6: =H2-H9 -> 15371064
A7: COGS % | C7: =C6/C$2 -> 0.97977203 | D7: =D6/D$2 -> 0.8783797 | E7: =E6/E$2 -> 0.91934201 | F7: =F6/F$2 -> 0.90157746 | G7: =G6/G$2 -> 0.91594853 | H7: =H6/H$2 -> 0.8895286
A9: Gross Profit | B9: 1185626 | C9: 283134 | D9: 1891181 | E9: 1282262 | F9: 1501370 | G9: 1293764 | H9: 1908947
A10: GPM% | B10: =+B9/B2 -> 0.068528601 | C10: =C9/C$2 -> 0.020227975 | D10: =D9/D$2 -> 0.1216203 | E10: =E9/E$2 -> 0.080657994 | F10: =F9/F$2 -> 0.09842254 | G10: =G9/G$2 -> 0.084051469 | H10: =H9/H$2 -> 0.1104714
A12: EBIT | B12: 772864 | C12: -582128 | D12: =+D18-D15 -> 1217053 | E12: 859610 | F12: 647884 | G12: =+G18-G15 -> 381975 | H12: 1908947
A13: EBIT margin % | B13: =+B12/B2 -> 0.04467116 | C13: =C12/C$2 -> -0.041589038 | D13: =D12/D$2 -> 0.078267678 | E13: =E12/E$2 -> 0.054071959 | F13: =F12/F$2 -> 0.042472135 | G13: =G12/G$2 -> 0.024815623 | H13: =H12/H$2 -> 0.1104714
A15: Net Finance Income/Cost | B15: -363780 | C15: -118995 | D15: 6968 | E15: -181936 | F15: -260940 | G15: -108269 | H15: -180545
A16: As a % of EBIT | B16: =+B15/B12 -> -0.47069083 | C16: =+C15/C12 -> 0.20441381 | D16: =+D15/D12 -> 0.0057253053 | E16: =+E15/E12 -> -0.21164947 | F16: =+F15/F12 -> -0.40275728 | G16: =+G15/G12 -> -0.28344525 | H16: =+H15/H12 -> -0.09457832
A18: PBT | B18: 409084 | C18: -701123 | D18: 1224021 | E18: 677674 | F18: 386944 | G18: 273706 | H18: 1004447
A19: PBT Margin% | B19: =+B18/B2 -> 0.023644854 | C19: =+C18/C2 -> -0.050090411 | D19: =+D18/D2 -> 0.078715784 | E19: =+E18/E2 -> 0.042627658 | F19: =+F18/F2 -> 0.025366173 | G19: =+G18/G2 -> 0.017781753 | H19: =+H18/H2 -> 0.058127683
A21: Taxes | B21: -256694 | C21: -151893 | D21: -281019 | E21: -200314 | F21: 162189 | G21: -115405 | H21: -248365
A22: ETR% | B22: =+B21/B18 -> -0.62748482 | C22: =+C21/C18 -> 0.21664244 | D22: =+D21/D18 -> -0.22958675 | E22: =+E21/E18 -> -0.29559051 | F22: =+F21/F18 -> 0.41915368 | G22: =+G21/G18 -> -0.42163855 | H22: =+H21/H18 -> -0.24726541
A24: Net Profit Attributable to Equity Holders | B24: =+B18+B21 -> 152390 | C24: =+C18+C21 -> -853016 | D24: =+D18+D21 -> 943002 | E24: =+E18+E21 -> 477360 | F24: =+F18+F21 -> 549133 | G24: =+G18+G21 -> 158301 | H24: 756082
A25: NP Margin | B25: =+B24/B2 -> 0.0088080672 | C25: =+C24/C2 -> -0.06094212 | D25: =+D24/D2 -> 0.060643683 | E25: =+E24/E2 -> 0.030027327 | F25: =+F24/F2 -> 0.035998498 | G25: =+G24/G2 -> 0.01028428 | H25: =+H24/H2 -> 0.043754718
A27: EPS | B27: =+B24/B43 -> 0.21261546 | C27: =+C24/C43 -> -1.1901331 | D27: =+D24/D43 -> 1.3156822 | E27: =+E24/E43 -> 0.66601559 | F27: =+F24/F43 -> 0.76615372 | G27: =+G24/G43 -> 0.22086252 | H27: 1.05
A28: YoY% | B28: =+B27/#REF!-1 -> #REF! | G28: =+G27/C27-1 -> -1.185578 | H28: =+H27/D27-1 -> -0.20193491
A29: QoQ% | B29: =+B27/#REF!-1 -> #REF! | C29: =+C27/B27-1 -> -6.5975851 | D29: =+D27/C27-1 -> -2.1054916 | E29: =+E27/D27-1 -> -0.49378686 | F29: =+F27/E27-1 -> 0.15035403 | G29: =+G27/F27-1 -> -0.71172557 | H29: =+H27/G27-1 -> 3.7540886
A31: RoE | B31: =+B24*4/B36 -> 0.019022974 | C31: =+C24*4/C37 -> -0.11573328 | D31: =+D24*4/D37 -> 0.11934432 | E31: =+E24*4/E37 -> 0.059332498 | F31: =+F24*4/F37 -> 0.072946743 | G31: =+G24*4/G37 -> 0.020795666
A33: Total asset | B33: =6238676+1329873+125243+6347896 -> 14041688
A34: Total Liability | B34: =3281426+7907029 -> 11188455
A35: Current asset | B35: =+B33-B34 -> 2853233
A36: Current Liability | B36: 32043359
A37: Equity | C37: 29482133 | D37: 31606096 | E37: 32182026 | F37: 30111447 | G37: 30448844
H38: =+C41/#REF!-1 -> #REF!
A39: Debt/Equity | B39: =+B33/B36 -> 0.43820899 | C39: =+C33/C37 -> 0 | D39: =+D33/D37 -> 0 | E39: =+E33/E37 -> 0 | F39: =+F33/F37 -> 0 | G39: =+G33/G37 -> 0
A41: Average Exchange rate (income Statement) | B41: =+(B2*1000)/#REF! -> #REF! | C41: =+(C2*1000)/#REF! -> #REF! | D41: =+(D2*1000)/#REF! -> #REF! | E41: =+(E2*1000)/#REF! -> #REF! | F41: =+(F2*1000)/#REF! -> #REF! | G41: =+(G2*1000)/#REF! -> #REF!
A43: Number of shares | B43: 716739.97 | C43: 716739.97 | D43: 716739.97 | E43: 716739.97 | F43: 716739.97 | G43: 716739.97
A45: Net Asset Value per share | B45: =+B36/B43 -> 44.707091 | C45: =+C37/C43 -> 41.133652 | D45: =+D37/D43 -> 44.097019 | E45: =+E37/E43 -> 44.90056 | F45: =+F37/F43 -> 42.011675 | G45: =+G37/G43 -> 42.482414
A47: Cashflow from operations (in LKR 000') | B47: =+B51-#REF! -> #REF! | C47: =+C51 -> 708033 | D47: =+D51-C51 -> 3097710 | E47: =+E51-D51 -> 1005237 | F47: =+F51-E51 -> -1400791 | G47: =+G51-F51 -> -2449397
A48: Capex | B48: =+B52-#REF! -> #REF! | C48: =+C52 -> -305304 | D48: =+D52-C52 -> -504882 | E48: =+E52-D52 -> -719042 | F48: =+F52-E52 -> -410914 | G48: =+G52 -> -173765
A49: FCF (in LKR 000') | B49: =+B47+B48 -> #REF! | C49: =+C47+C48 -> 402729 | D49: =+D47+D48 -> 2592828 | E49: =+E47+E48 -> 286195 | F49: =+F47+F48 -> -1811705 | G49: =+G47+G48 -> -2623162
A51: Cashflow from operations (in LKR 000') | B51: 7904112 | C51: 708033 | D51: 3805743 | E51: 4810980 | F51: 3410189 | G51: 960792
A52: Capex | B52: -3634954 | C52: -305304 | D52: -810186 | E52: -1529228 | F52: -1940142 | G52: -173765
A53: FCF (in LKR 000') | B53: =+B51+B52 -> 4269158 | C53: =+C51+C52 -> 402729 | D53: =+D51+D52 -> 2995557 | E53: =+E51+E52 -> 3281752 | F53: =+F51+F52 -> 1470047 | G53: =+G51+G52 -> 787027

Sheet BPPL
W1: Stock Price | X1: =+'Valuation Sheet'!C5 -> 18.4
B2: TJL - Rs mn | C2: FY16 | D2: FY17 | E2: FY18 | F2: FY19 | G2: FY20 | H2: FY21 | I2: FY22 | J2: CAGR/AVG | M2: MPS | N2: ='[1]LT Portfolio'!I294 -> SELL | P2: AVG | Q2: =J14*J21 -> #DIV/0! | W2: BPPL | X2: 2Q21 | Y2: 3Q21 | Z2: 4Q21 | AA2: 1Q22 | AB2: 2Q22 | AC2: 3Q22 | AD2: 4Q22 | AE2: 1Q23 | AF2: 2Q23 | AG2: 3Q23 | AH2: 4Q23 | AI2: 1Q24 | AJ2: 2Q24 | AK2: 3Q24 | AL2: 4Q24 | AM2: 1Q25 | AP2: =+W2 -> BPPL | AQ2: FY24E | AV2: FY25E | BE2: 1Q | BF2: 2Q | BG2: 3Q | BH2: 4Q
B3: Net Revenue | C3: 17820.179 | M3: P/E | N3: ='[1]LT Portfolio'!W294 -> 0 | W3: Revenue (LKR 000) | X3: 892337.88 | Y3: 896770.81 | Z3: 1055051.6 | AA3: 1005142.4 | AB3: 1152804.1 | AC3: 1253127 | AD3: 1397553.2 | AE3: 1585565.2 | AF3: 1713112.1 | AG3: 1445926 | AH3: 1506287 | AI3: 1158914 | AJ3: 1531197 | AK3: 1520706 | AL3: 1488408 | AM3: 1393105 | AQ3: Revenue | AR3: EBIT | AS3: NP | AT3: EPS | AU3: DPS | AV3: Revenue | AW3: EBIT | AX3: NP | AY3: EPS | AZ3: DPS | BD3: Revenue | BE3: =+AI3 -> 1158914 | BF3: =+AJ3 -> 1531197 | BG3: =+AK3 -> 1520706 | BH3: =+AL3 -> 1488408
B4: Revenue Growth | D4: =(D3/C3-1)*100 -> -100 | E4: =(E3/D3-1)*100 -> #DIV/0! | F4: =(F3/E3-1)*100 -> #DIV/0! | G4: =(G3/F3-1)*100 -> #DIV/0! | H4: =(H3/G3-1)*100 -> #DIV/0! | I4: =(I3/H3-1)*100 -> #DIV/0! | J4: =((I3/D3)^(1/5)-1)*100 -> #DIV/0! | W4: YoY% | AB4: =+AB3/X3-1 -> 0.29189194 | AC4: =+AC3/Y3-1 -> 0.39737711 | AD4: =+AD3/Z3-1 -> 0.32463018 | AE4: =+AE3/AA3-1 -> 0.57745319 | AF4: =+AF3/AB3-1 -> 0.48603921 | AG4: =+AG3/AC3-1 -> 0.15385432 | AH4: =+AH3/AD3-1 -> 0.077802978 | AI4: =+AI3/AE3-1 -> -0.26908459 | ... AM4: =+AM3/AI3-1 -> 0.20207798 | AP4: CT CLSA | BD4: GP | BE4: =+AI11 -> 208405 | BF4: =+AJ11 -> 450930 | BG4: =+AK11 -> 350186 | BH4: =+AL11 -> 351383
B5: Gross Profit | C5: 2994.862 | M5: 2Q21 | N5: =202.575/415.481776 -> 0.48756651 | W5: QoQ% | Y5: =+Y3/X3-1 -> 0.0049677651 | Z5: =+Z3/Y3-1 -> 0.17650084 | AA5: =+AA3/Z3-1 -> -0.047304951 | AB5: =+AB3/AA3-1 -> 0.14690621 | AC5: =+AC3/AB3-1 -> 0.087025094 | AD5: =+AD3/AC3-1 -> 0.11525264 | AE5: =+AE3/AD3-1 -> 0.13452937 | AF5: =+AF3/AE3-1 -> 0.080442586 | ... AM5: =+AM3/AL3-1 -> -0.064030158 | AP5: Capital Alliance | BD5: OP | BE5: =+AI14 -> 145690 | BF5: =+AJ14 -> 161492 | BG5: =+AK14 -> 220228 | BH5: =+AL14 -> 256133.88
B6: GPM | C6: =C5/C$3*100 -> 16.806015 | D6: =D5/D$3*100 -> #DIV/0! | E6: =E5/E$3*100 -> #DIV/0! | F6: =F5/F$3*100 -> #DIV/0! | G6: =G5/G$3*100 -> #DIV/0! | H6: =H5/H$3*100 -> #DIV/0! | I6: =I5/I$3*100 -> #DIV/0! | J6: =AVERAGE(D6:I6) -> #DIV/0! | M6: 3Q21 | N6: =261.001/415.481776 -> 0.6281888 | AP6: Asia Securities | BD6: NP | BE6: =+AI26 -> 61355 | BF6: =+AJ26 -> 98923 | BG6: =+AK26 -> 88445 | BH6: =+AL26 -> 253509.36
B7: EBIT | C7: 2167.608 | M7: 4Q21 | N7: ='[1]LT Portfolio'!P294 -> 0 | W7: Revenue (in USD) | X7: =+X3/X42 -> 4749.5945 | Y7: =+Y3/Y42 -> 4772.5109 | Z7: =+Z3/Z42 -> 5331.2759 | AA7: =+AA3/AA42 -> 4978.746 | AB7: =+AB3/AB42 -> 5680.7038 | AC7: =+AC3/AC42 -> 6173.0392 | AD7: =+AD3/AD42 -> 5985.7965 | AE7: =+AE3/AE42 -> 4352.6799 | ... AM7: =+AM3/AM42 -> #DIV/0! | AP7: First Capital | BD7: EPS | BE7: =+AI29 -> 0.19995545 | BF7: =+AJ29 -> 0.32238925 | BG7: =+AK29 -> 0.28824153 | BH7: =+AL29 -> 0.82618493
B8: EBIT Margin | C8: =C7/C$3*100 -> 12.163784 | D8: =D7/D$3*100 -> #DIV/0! | E8: =E7/E$3*100 -> #DIV/0! | F8: =F7/F$3*100 -> #DIV/0! | G8: =G7/G$3*100 -> #DIV/0! | H8: =H7/H$3*100 -> #DIV/0! | I8: =I7/I$3*100 -> #DIV/0! | J8: =AVERAGE(D8:I8) -> #DIV/0! | M8: 1Q22 | N8: ='[1]LT Portfolio'!Q294 -> 0 | W8: YoY% | AB8: =+AB7/X7-1 -> 0.19603974 | AC8: =+AC7/Y7-1 -> 0.29345733 | AD8: =+AD7/Z7-1 -> 0.12276999 | AE8: =+AE7/AA7-1 -> -0.12574775 | AF8: =+AF7/AB7-1 -> -0.18241155 | AG8: =+AG7/AC7-1 -> -0.36996259 | AH8: =+AH7/AD7-1 -> -0.29646666 | AI8: =+AI7/AE7-1 -> -0.15864314 | ... AM8: =+AM7/AI7-1 -> #DIV/0! | AP8: Bartleet
B9: PBT | C9: 2228.947 | M9: 2Q22 | N9: ='[1]LT Portfolio'!R294 -> 0 | O9: =N9/N5-1 -> -1 | W9: QoQ% | Y9: =+Y7/X7-1 -> 0.0048249125 | Z9: =+Z7/Y7-1 -> 0.11707987 | AA9: =+AA7/Z7-1 -> -0.066124859 | AB9: =+AB7/AA7-1 -> 0.14099088 | AC9: =+AC7/AB7-1 -> 0.086668036 | AD9: =+AD7/AC7-1 -> -0.030332333 | AE9: =+AE7/AD7-1 -> -0.27283197 | AF9: =+AF7/AE7-1 -> 0.06703868 | ... AM9: =+AM7/AL7-1 -> #DIV/0! | AP9: NDBS | AQ9: 8454 | AR9: 1726 | AS9: 1031 | AT9: 3.36 | AU9: 0.42 | AV9: 11369 | AW9: 2644 | AX9: 1760 | AY9: 5.73 | AZ9: 0.42 | BD9: GPM | BE9: =+BE4/BE$3*100 -> 17.982784 | BF9: =+BF4/BF$3*100 -> 29.449509 | BG9: =+BG4/BG$3*100 -> 23.027857 | BH9: =+BH4/BH$3*100 -> 23.607976
B10: Net Profit | C10: 2170.667 | J10: =((I10/D10)^(1/5)-1)*100 -> #DIV/0! | M10: 3Q22 | N10: ='[1]LT Portfolio'!S294 -> 0 | O10: =N10/N6-1 -> -1 | AP10: JKSB | BD10: OPM | BE10: =+BE5/BE$3*100 -> 12.571252 | BF10: =+BF5/BF$3*100 -> 10.546781 | BG10: =+BG5/BG$3*100 -> 14.481958 | BH10: =+BH5/BH$3*100 -> 17.20858
B11: NP Margin | C11: =C10/C$3*100 -> 12.180949 | D11: =D10/D$3*100 -> #DIV/0! | E11: =E10/E$3*100 -> #DIV/0! | F11: =F10/F$3*100 -> #DIV/0! | G11: =G10/G$3*100 -> #DIV/0! | H11: =H10/H$3*100 -> #DIV/0! | I11: =I10/I$3*100 -> #DIV/0! | J11: =AVERAGE(D11:I11) -> #DIV/0! | M11: 4Q22 | N11: ='[1]LT Portfolio'!T294 -> 0 | O11: =N11/N7-1 -> #DIV/0! | W11: Gross Profit | X11: 311138.53 | Y11: 311186.91 | Z11: 375132.08 | AA11: 307416.65 | AB11: 338985.05 | AC11: 342614 | AD11: 416715.15 | AE11: 619340.26 | AF11: 547987.64 | AG11: 412787 | AH11: 281414 | AI11: 208405 | AJ11: 450930 | AK11: 350186 | AL11: 351383 | AM11: 326232 | AP11: Consensus | AQ11: =+AVERAGE(AQ4:AQ10) -> 8454 | AR11: =+AVERAGE(AR4:AR10) -> 1726 | AS11: =+AVERAGE(AS4:AS10) -> 1031 | AT11: =+AVERAGE(AT4:AT10) -> 3.36 | AU11: =+AVERAGE(AU4:AU10) -> 0.42 | AV11: =+AVERAGE(AV4:AV10) -> 11369 | AW11: =+AVERAGE(AW4:AW10) -> 2644 | AX11: =+AVERAGE(AX4:AX10) -> 1760 | ... AZ11: =+AVERAGE(AZ4:AZ10) -> 0.42 | BD11: NPM | BE11: =+BE6/BE$3*100 -> 5.2941806 | BF11: =+BF6/BF$3*100 -> 6.4605012 | BG11: =+BG6/BG$3*100 -> 5.8160486 | BH11: =+BH6/BH$3*100 -> 17.032249
B12: NP Growth | D12: =(D10/C10-1)*100 -> -100 | E12: =(E10/D10-1)*100 -> #DIV/0! | F12: =(F10/E10-1)*100 -> #DIV/0! | G12: =(G10/F10-1)*100 -> #DIV/0! | H12: =(H10/G10-1)*100 -> #DIV/0! | I12: =(I10/H10-1)*100 -> #DIV/0! | J12: =AVERAGE(D12:I12) -> #DIV/0! | S12: 1Q22 | T12: 2Q22 | W12: GPM% | X12: =+X11/X3 -> 0.34867793 | Y12: =+Y11/Y3 -> 0.3470083 | Z12: =+Z11/Z3 -> 0.35555804 | AA12: =+AA11/AA3 -> 0.30584386 | AB12: =+AB11/AB3 -> 0.2940526 | AC12: =+AC11/AC3 -> 0.27340724 | AD12: =+AD11/AD3 -> 0.2981748 | AE12: =+AE11/AE3 -> 0.39061167 | ... AM12: =+AM11/AM3 -> 0.23417617 | AU12: DY | AZ12: DY
M13: TTM | N13: =SUM(N8:N11) -> 0 | Q13: =N13*J21 -> #DIV/0! | S13: 19.109574 | T13: 18.873653 | AP13: Leading P/E | AT13: =+$X$1/AT11 -> 5.4761905 | AU13: =+AU11/$X$1 -> 0.022826087 | AY13: =+$X$1/AY11 -> 3.2111693 | AZ13: =+AZ11/$X$1 -> 0.022826087
B14: EPS | C14: 3.24 | J14: =AVERAGE(D14:I14) -> #DIV/0! | M14: P/E | N14: =N2/N13 -> #VALUE! | Q14: =Q13/N2-1 -> #DIV/0! | S14: =S13/N2-1 -> #VALUE! | T14: =T13/N2-1 -> #VALUE! | W14: EBIT | X14: =+X20-X17 -> 175971.5 | Y14: =+Y20-Y17 -> 157600.41 | Z14: =+Z20-Z17 -> 213998.57 | AA14: =+AA20-AA17 -> 141542.46 | AB14: =+AB20-AB17 -> 170023.22 | AC14: =+AC20-AC17 -> 131202 | AD14: =+AD20-AD17 -> 327672.05 | AE14: =+AE20-AE17 -> 434847.96 | ... AM14: =+AM20-AM17 -> 88129
B15: DPS | C15: =1+0.6 -> 1.6 | W15: EBIT margin % | X15: =+X14/X3 -> 0.19720277 | Y15: =+Y14/Y3 -> 0.17574212 | Z15: =+Z14/Z3 -> 0.20283232 | AA15: =+AA14/AA3 -> 0.14081831 | AB15: =+AB14/AB3 -> 0.14748665 | AC15: =+AC14/AC3 -> 0.10469968 | AD15: =+AD14/AD3 -> 0.23446123 | AE15: =+AE14/AE3 -> 0.27425424 | ... AM15: =+AM14/AM3 -> 0.063260845
B16: MPS | C16: 31.7 | J16: =((I16/D16)^(1/5)-1)*100 -> #DIV/0!
B17: BVPS | C17: 14.6 | J17: =((I17/D17)^(1/6)-1)*100 -> #DIV/0! | W17: Net Finance Income/Cost | X17: -10365.329 | Y17: -7177.808 | Z17: -6734.965 | AA17: =-15701.342+7239.066 -> -8462.276 | AB17: -9462.69 | AC17: -12318 | AD17: -22313.5 | AE17: =-64237.103+3416.424 -> -60820.679 | AF17: -78636.354 | AG17: -83080 | AH17: -83330 | AI17: -69832 | AJ17: -79158 | AK17: -72523 | AL17: -59600 | AM17: -73298
B18: ROE | C18: =C14/AVERAGE(B17:C17)*100 -> 22.191781 | D18: =D14/AVERAGE(C17:D17)*100 -> 0 | E18: =E14/AVERAGE(D17:E17)*100 -> #DIV/0! | F18: =F14/AVERAGE(E17:F17)*100 -> #DIV/0! | G18: =G14/AVERAGE(F17:G17)*100 -> #DIV/0! | H18: =H14/AVERAGE(G17:H17)*100 -> #DIV/0! | I18: =I14/AVERAGE(H17:I17)*100 -> #DIV/0! | J18: =AVERAGE(D18:I18) -> #DIV/0! | M18: MGT | W18: As a % of EBIT | X18: =+X17/X14 -> -0.058903453 | Y18: =+Y17/Y14 -> -0.04554435 | Z18: =+Z17/Z14 -> -0.031472009 | AA18: =+AA17/AA14 -> -0.059786131 | AB18: =+AB17/AB14 -> -0.05565528 | AC18: =+AC17/AC14 -> -0.093885764 | AD18: =+AD17/AD14 -> -0.06809705 | AE18: =+AE17/AE14 -> -0.13986654 | ... AM18: =+AM17/AM14 -> -0.8317126
B19: DY | C19: =C15/C16*100 -> 5.0473186 | D19: =D15/D16*100 -> #DIV/0! | E19: =E15/E16*100 -> #DIV/0! | F19: =F15/F16*100 -> #DIV/0! | G19: =G15/G16*100 -> #DIV/0! | H19: =H15/H16*100 -> #DIV/0! | I19: =I15/I16*100 -> #DIV/0! | J19: =AVERAGE(D19:I19) -> #DIV/0!
B20: Dividend Payout | C20: =C15/C14*100 -> 49.382716 | D20: =D15/D14*100 -> #DIV/0! | E20: =E15/E14*100 -> #DIV/0! | F20: =F15/F14*100 -> #DIV/0! | G20: =G15/G14*100 -> #DIV/0! | H20: =H15/H14*100 -> #DIV/0! | I20: =I15/I14*100 -> #DIV/0! | J20: =AVERAGE(D20:I20) -> #DIV/0! | M20: YoY Growth | N20: =N13/H14-1 -> #DIV/0! | W20: PBT | X20: 165606.17 | Y20: 150422.6 | Z20: 207263.61 | AA20: 133080.18 | AB20: 160560.53 | AC20: 118884 | AD20: 305358.55 | AE20: 374027.28 | AF20: 236816.41 | AG20: 136962 | AH20: -41370 | AI20: 75858 | AJ20: 82334 | AK20: 147705 | AL20: =+AL84-AK20-AJ20-AI20 -> 196533.88 | AM20: 14831
B21: P/E | C21: =C16/C14 -> 9.7839506 | D21: =D16/D14 -> #DIV/0! | E21: =E16/E14 -> #DIV/0! | F21: =F16/F14 -> #DIV/0! | G21: =G16/G14 -> #DIV/0! | H21: =H16/H14 -> #DIV/0! | I21: =I16/I14 -> #DIV/0! | J21: =AVERAGE(D21:I21) -> #DIV/0! | W21: PBT Margin% | X21: =+X20/X3 -> 0.18558684 | Y21: =+Y20/Y3 -> 0.16773806 | Z21: =+Z20/Z3 -> 0.19644878 | AA21: =+AA20/AA3 -> 0.13239933 | AB21: =+AB20/AB3 -> 0.13927824 | AC21: =+AC20/AC3 -> 0.094869874 | AD21: =+AD20/AD3 -> 0.21849512 | AE21: =+AE20/AE3 -> 0.23589525 | ... AM21: =+AM20/AM3 -> 0.010646003
B22: P/B | C22: =C16/C17 -> 2.1712329 | D22: =D16/D17 -> #DIV/0! | E22: =E16/E17 -> #DIV/0! | F22: =F16/F17 -> #DIV/0! | G22: =G16/G17 -> #DIV/0! | H22: =H16/H17 -> #DIV/0! | I22: =I16/I17 -> #DIV/0! | J22: =AVERAGE(D22:I22) -> #DIV/0!
W23: Taxes | X23: -30822.281 | Y23: -21391.238 | Z23: -33928.704 | AA23: -28780.983 | AB23: -33158.298 | AC23: =-14900-6485 -> -21385 | AD23: -46580.095 | AE23: -73659.358 | AF23: -14322.784 | AG23: =-39933-139450 -> -179383 | AH23: =2038+70050 -> 72088 | AI23: =-18452+3949 -> -14503 | AJ23: 16589 | AK23: -59260 | AL23: =+AL85-AI23-AJ23-AK23 -> 56975.477 | AM23: =-28944-4761 -> -33705
G24: 701.95658 | H24: 709.32254 | I24: 716.73997 | W24: ETR% | X24: =+X23/X20 -> -0.18611795 | Y24: =+Y23/Y20 -> -0.14220761 | Z24: =+Z23/Z20 -> -0.16369832 | AA24: =+AA23/AA20 -> -0.21626798 | AB24: =+AB23/AB20 -> -0.20651587 | AC24: =+AC23/AC20 -> -0.17988123 | AD24: =+AD23/AD20 -> -0.1525423 | AE24: =+AE23/AE20 -> -0.19693579 | ... AM24: =+AM23/AM20 -> -2.2726047
G25: =+G10/G24 -> 0 | H25: =+H10/H24 -> 0 | I25: =+I10/I24 -> 0
W26: Net Profit Attributable to Equity Holders | X26: =+X20+X23 -> 134783.89 | Y26: =+Y20+Y23 -> 129031.36 | Z26: =+Z20+Z23 -> 173334.9 | AA26: =+AA20+AA23 -> 104299.2 | AB26: =+AB20+AB23 -> 127402.23 | AC26: =+AC20+AC23 -> 97499 | AD26: =+AD20+AD23 -> 258778.45 | AE26: =+AE20+AE23 -> 300367.93 | ... AM26: =+AM20+AM23 -> -18874
W27: NP Margin | X27: =+X26/X3 -> 0.1510458 | Y27: =+Y26/Y3 -> 0.14388443 | Z27: =+Z26/Z3 -> 0.16429045 | AA27: =+AA26/AA3 -> 0.10376559 | AB27: =+AB26/AB3 -> 0.11051507 | AC27: =+AC26/AC3 -> 0.077804564 | AD27: =+AD26/AD3 -> 0.18516537 | AE27: =+AE26/AE3 -> 0.18943903 | ... AM27: =+AM26/AM3 -> -0.013548153
W29: EPS | X29: =+X26/X44 -> 0.4392596 | Y29: =+Y26/Y44 -> 0.42051215 | Z29: =+Z26/Z44 -> 0.56489703 | AA29: =+AA26/AA44 -> 0.33991024 | AB29: =+AB26/AB44 -> 0.41520284 | AC29: =+AC26/AC44 -> 0.31774845 | AD29: =+AD26/AD44 -> 0.84335687 | AE29: =+AE26/AE44 -> 0.97889663 | ... AM29: =+AM26/AM44 -> -0.061510212
W30: YoY% | AB30: =+AB29/X29-1 -> -0.054766619 | AC30: =+AC29/Y29-1 -> -0.24437749 | AD30: =+AD29/Z29-1 -> 0.49293912 | AE30: =+AE29/AA29-1 -> 1.879868 | AF30: =+AF29/AB29-1 -> 0.74638718 | AG30: =+AG29/AC29-1 -> -1.4350916 | AH30: =+AH29/AD29-1 -> -0.88129615 | AI30: =+AI29/AE29-1 -> -0.79573385 | ... AM30: =+AM29/AI29-1 -> -1.3076196
W31: QoQ% | Y31: =+Y29/X29-1 -> -0.042679663 | Z31: =+Z29/Y29-1 -> 0.34335483 | AA31: =+AA29/Z29-1 -> -0.39827929 | AB31: =+AB29/AA29-1 -> 0.22150729 | AC31: =+AC29/AB29-1 -> -0.23471514 | AD31: =+AD29/AC29-1 -> 1.6541652 | AE31: =+AE29/AD29-1 -> 0.16071459 | AF31: =+AF29/AE29-1 -> -0.25926304 | ... AM31: =+AM29/AL29-1 -> -1.0744509
W33: RoE | X33: =+X26*4/X38 -> 0.17512429 | Y33: =+Y26*4/Y38 -> 0.16125518 | Z33: =+Z26*4/Z38 -> 0.21392051 | AA33: =+AA26*4/AA38 -> 0.12444602 | AB33: =+AB26*4/AB38 -> 0.16604009 | AC33: =+AC26*4/AC38 -> 0.11045142 | AD33: =+AD26*4/AD38 -> 0.3437744 | AE33: =+AE26*4/AE38 -> 0.41273896 | ... AM33: =+AM26*4/AM38 -> -0.018800495 | AO33: =+AVERAGE(X33:AM33) -> 0.15382125 | AP33: RoE
AO34: =AVERAGE(X33:AM33)*AM46 -> 2.0130486 | AP34: Normalized EPS
W35: Debt | X35: =426032.725+43189.375+947386.696 -> 1416608.8 | Y35: =1056608.135+40504.796+419040.114 -> 1516153 | Z35: =825943.002+36009.829+1737.629+1037079.851 -> 1900770.3 | AA35: =999991.123+36982.83-1999.5+1251100.352 -> 2286074.8 | AB35: =1910009.447+228766.544+2091814.003+870.389 -> 4231460.4 | AC35: =1930726+36236+1117388 -> 3084350 | AD35: =2030315.505+35135.746+872.487+1971507.945 -> 4037831.7 | AE35: =1783721.111+34900.99+872.487+2876409.838 -> 4695904.4 | AF35: =1760634.388+34659.12+22100.72+2760257.49 -> 4577651.7 | AG35: =2069054+47698+1740380+6176 -> 3863308 | AH35: =1231028+36086+1936017+10996 -> 3214127 | AI35: =1481395+36843+1418958+10996 -> 2948192 | AJ35: =974946+36539+8144+2106053 -> 3125682 | AK35: =974946+33333+8099+1883544 -> 2899922 | AL35: =705541+32781+2179+2037051 -> 2777552 | AM35: =840036+98556+76581+2072056 -> 3087229 | AO35: =X1/AO34 -> 9.1403653 | AP35: P/E
W36: Cash | X36: 328900.05 | Y36: 335189.23 | Z36: =275808.326+55498.469 -> 331306.79 | AA36: =232498.822+282848.236 -> 515347.06 | AB36: =115561.187+59077.6 -> 174638.79 | AC36: =687380+180483 -> 867863 | AD36: =115561.187+59077.6 -> 174638.79 | AE36: =281309.783+62346.154 -> 343655.94 | AF36: =192217.469+66379.769 -> 258597.24 | AG36: 150104 | AH36: 185416 | AI36: 65982 | AJ36: 111761 | AK36: 124546 | AL36: 35446 | AM36: =95485+30240 -> 125725
W37: Net Debt | X37: =+X35-X36 -> 1087708.7 | Y37: =+Y35-Y36 -> 1180963.8 | Z37: =+Z35-Z36 -> 1569463.5 | AA37: =+AA35-AA36 -> 1770727.7 | AB37: =+AB35-AB36 -> 4056821.6 | AC37: =+AC35-AC36 -> 2216487 | AD37: =+AD35-AD36 -> 3863192.9 | AE37: =+AE35-AE36 -> 4352248.5 | ... AM37: =+AM35-AM36 -> 2961504
W38: Equity | X38: 3078588.2 | Y38: 3200675.1 | Z38: 3241108.6 | AA38: 3352431.8 | AB38: 3069192 | AC38: 3530928 | AD38: 3011026.4 | AE38: 2910972.3 | AF38: 3209857.4 | AG38: 3243912 | AH38: 3615384 | AI38: 3676739 | AJ38: 3775661 | AK38: 3864106 | AL38: 4053820 | AM38: 4015639
W40: Debt/Equity | X40: =+X35/X38 -> 0.46014884 | Y40: =+Y35/Y38 -> 0.47369789 | Z40: =+Z35/Z38 -> 0.58645684 | AA40: =+AA35/AA38 -> 0.68191538 | AB40: =+AB35/AB38 -> 1.3786887 | AC40: =+AC35/AC38 -> 0.8735239 | AD40: =+AD35/AD38 -> 1.341015 | AE40: =+AE35/AE38 -> 1.6131738 | ... AM40: =+AM35/AM38 -> 0.76880143
W42: Average Exchange rate (income Statement) | X42: =+MGT!X42 -> 187.87665 | Y42: =+MGT!Y42 -> 187.90336 | Z42: =+MGT!Z42 -> 197.89852 | AA42: =+MGT!AA42 -> 201.88667 | AB42: =+MGT!AB42 -> 202.93333 | AC42: =+MGT!AC42 -> 203.00001 | AD42: =+MGT!AD42 -> 233.47823 | AE42: =+MGT!AE42 -> 364.27332 | ... AL42: =+MGT!AL42 -> 311.04853 | AM42: =+MGT!AN42 -> 0
W44: Number of shares | X44: 306843.36 | Y44: 306843.36 | Z44: 306843.36 | AA44: 306843.36 | AB44: 306843.36 | AC44: 306843.36 | AD44: 306843.36 | AE44: 306843.36 | AF44: 306843.36 | AG44: 306843.36 | AH44: 306843.36 | AI44: 306843.36 | AJ44: 306843.36 | AK44: 306843.36 | AL44: 306843.36 | AM44: 306843.36
W46: Net Asset Value per share | X46: =+X38/X44 -> 10.033094 | Y46: =+Y38/Y44 -> 10.430974 | Z46: =+Z38/Z44 -> 10.562747 | AA46: =+AA38/AA44 -> 10.925548 | AB46: =+AB38/AB44 -> 10.002472 | AC46: =+AC38/AC44 -> 11.507266 | AD46: =+AD38/AD44 -> 9.8129106 | AE46: =+AE38/AE44 -> 9.4868351 | ... AM46: =+AM38/AM44 -> 13.086935
...

Sheet HAYL
W1: Stock Price | X1: =+'Valuation Sheet'!C6 -> 95.6
B2: TJL - Rs mn | C2: FY16 | D2: FY17 | E2: FY18 | F2: FY19 | G2: FY20 | H2: FY21 | I2: FY22 | J2: CAGR/AVG | M2: MPS | N2: ='[1]LT Portfolio'!I294 -> SELL | P2: AVG | Q2: =J14*J21 -> #DIV/0! | W2: HAYL | X2: 2Q21 | Y2: 3Q21 | Z2: 4Q21 | AA2: 1Q22 | AB2: 2Q22 | AC2: 3Q22 | AD2: 4Q22 | AE2: 1Q23 | AF2: 2Q23 | AG2: 3Q23 | AH2: 4Q23 | AI2: 1Q24 | AJ2: 2Q24 | AK2: 3Q24 | AL2: 4Q24 | AM2: 1Q25 | AO2: =+W2 -> HAYL | AP2: FY24E | AU2: FY25E
B3: Net Revenue | C3: 17820.179 | M3: P/E | N3: ='[1]LT Portfolio'!W294 -> 0 | W3: Revenue (LKR 000) | AB3: 79438158 | AC3: 92217650 | AD3: 95743008 | AE3: 123641304 | AF3: 129931777 | AG3: 116350572 | AH3: 117507228 | AI3: 96938050 | AJ3: 105256047 | AK3: 122302403 | AL3: 112336770 | AM3: 113607627 | AP3: Revenue | AQ3: EBIT | AR3: NP | AS3: EPS | AT3: DPS | AU3: Revenue | AV3: EBIT | AW3: NP | AX3: EPS | AY3: DPS
B4: Revenue Growth | D4: =(D3/C3-1)*100 -> -100 | E4: =(E3/D3-1)*100 -> #DIV/0! | F4: =(F3/E3-1)*100 -> #DIV/0! | G4: =(G3/F3-1)*100 -> #DIV/0! | H4: =(H3/G3-1)*100 -> #DIV/0! | I4: =(I3/H3-1)*100 -> #DIV/0! | J4: =((I3/D3)^(1/5)-1)*100 -> #DIV/0! | W4: YoY% | AB4: =+AB3/X3-1 -> #DIV/0! | AC4: =+AC3/Y3-1 -> #DIV/0! | AD4: =+AD3/Z3-1 -> #DIV/0! | AE4: =+AE3/AA3-1 -> #DIV/0! | AF4: =+AF3/AB3-1 -> 0.63563431 | AG4: =+AG3/AC3-1 -> 0.26169526 | AH4: =+AH3/AD3-1 -> 0.22731916 | AI4: =+AI3/AE3-1 -> -0.21597357 | ... AM4: =+AM3/AI3-1 -> 0.17196113 | AO4: Acuity | AP4: 416563 | AQ4: 36452 | AR4: 6892 | AS4: 9.19 | AU4: 448372 | AV4: 42475 | AW4: 13460 | AX4: 17.95
B5: Gross Profit | C5: 2994.862 | M5: 2Q21 | N5: =202.575/415.481776 -> 0.48756651 | W5: QoQ% | Y5: =+Y3/X3-1 -> #DIV/0! | Z5: =+Z3/Y3-1 -> #DIV/0! | AA5: =+AA3/Z3-1 -> #DIV/0! | AB5: =+AB3/AA3-1 -> #DIV/0! | AC5: =+AC3/AB3-1 -> 0.16087347 | AD5: =+AD3/AC3-1 -> 0.038228669 | AE5: =+AE3/AD3-1 -> 0.29138729 | AF5: =+AF3/AE3-1 -> 0.050876793 | ... AM5: =+AM3/AL3-1 -> 0.011312921
B6: GPM | C6: =C5/C$3*100 -> 16.806015 | D6: =D5/D$3*100 -> #DIV/0! | E6: =E5/E$3*100 -> #DIV/0! | F6: =F5/F$3*100 -> #DIV/0! | G6: =G5/G$3*100 -> #DIV/0! | H6: =H5/H$3*100 -> #DIV/0! | I6: =I5/I$3*100 -> #DIV/0! | J6: =AVERAGE(D6:I6) -> #DIV/0! | M6: 3Q21 | N6: =261.001/415.481776 -> 0.6281888
B7: EBIT | C7: 2167.608 | M7: 4Q21 | N7: ='[1]LT Portfolio'!P294 -> 0 | W7: Revenue (in USD) | AB7: =+AB3/AB44 -> 391449.54 | AC7: =+AC3/AC44 -> 454274.12 | AD7: =+AD3/AD44 -> 410072.52 | AE7: =+AE3/AE44 -> 339419.05 | AF7: =+AF3/AF44 -> 352262.56 | AG7: =+AG3/AG44 -> 312959.27 | AH7: =+AH3/AH44 -> 328521.26 | AI7: =+AI3/AI44 -> 306323.31 | ... AM7: =+AM3/AM44 -> 371351.71
B8: EBIT Margin | C8: =C7/C$3*100 -> 12.163784 | D8: =D7/D$3*100 -> #DIV/0! | E8: =E7/E$3*100 -> #DIV/0! | F8: =F7/F$3*100 -> #DIV/0! | G8: =G7/G$3*100 -> #DIV/0! | H8: =H7/H$3*100 -> #DIV/0! | I8: =I7/I$3*100 -> #DIV/0! | J8: =AVERAGE(D8:I8) -> #DIV/0! | M8: 1Q22 | N8: ='[1]LT Portfolio'!Q294 -> 0 | W8: YoY% | AB8: =+AB7/X7-1 -> #DIV/0! | AC8: =+AC7/Y7-1 -> #DIV/0! | AD8: =+AD7/Z7-1 -> #DIV/0! | AE8: =+AE7/AA7-1 -> #DIV/0! | AF8: =+AF7/AB7-1 -> -0.10010738 | AG8: =+AG7/AC7-1 -> -0.31107836 | AH8: =+AH7/AD7-1 -> -0.19887033 | AI8: =+AI7/AE7-1 -> -0.097507029 | ... AM8: =+AM7/AI7-1 -> 0.21228685
B9: PBT | C9: 2228.947 | M9: 2Q22 | N9: ='[1]LT Portfolio'!R294 -> 0 | O9: =N9/N5-1 -> -1 | W9: QoQ% | Y9: =+Y7/X7-1 -> #DIV/0! | Z9: =+Z7/Y7-1 -> #DIV/0! | AA9: =+AA7/Z7-1 -> #DIV/0! | AB9: =+AB7/AA7-1 -> #DIV/0! | AC9: =+AC7/AB7-1 -> 0.16049215 | AD9: =+AD7/AC7-1 -> -0.097301605 | AE9: =+AE7/AD7-1 -> -0.17229507 | AF9: =+AF7/AE7-1 -> 0.037839678 | ... AM9: =+AM7/AL7-1 -> 0.028233259
B10: Net Profit | C10: 2170.667 | J10: =((I10/D10)^(1/5)-1)*100 -> #DIV/0! | M10: 3Q22 | N10: ='[1]LT Portfolio'!S294 -> 0 | O10: =N10/N6-1 -> -1
B11: NP Margin | C11: =C10/C$3*100 -> 12.180949 | D11: =D10/D$3*100 -> #DIV/0! | E11: =E10/E$3*100 -> #DIV/0! | F11: =F10/F$3*100 -> #DIV/0! | G11: =G10/G$3*100 -> #DIV/0! | H11: =H10/H$3*100 -> #DIV/0! | I11: =I10/I$3*100 -> #DIV/0! | J11: =AVERAGE(D11:I11) -> #DIV/0! | M11: 4Q22 | N11: ='[1]LT Portfolio'!T294 -> 0 | O11: =N11/N7-1 -> #DIV/0! | W11: Gross Profit | AB11: 17634178 | AC11: 21646404 | AD11: 21788356 | AE11: 32477265 | AF11: 29685645 | AG11: 28693187 | AH11: 28377936 | AI11: 22642278 | AJ11: 25208153 | AK11: 29935583 | AL11: 31639764 | AM11: 25961963 | AO11: Consensus | AP11: =+AVERAGE(AP4:AP10) -> 416563 | AQ11: =+AVERAGE(AQ4:AQ10) -> 36452 | AR11: =+AVERAGE(AR4:AR10) -> 6892 | AS11: =+AVERAGE(AS4:AS10) -> 9.19 | AT11: =+AVERAGE(AT4:AT10) -> #DIV/0! | AU11: =+AVERAGE(AU4:AU10) -> 448372 | AV11: =+AVERAGE(AV4:AV10) -> 42475 | AW11: =+AVERAGE(AW4:AW10) -> 13460 | ... AY11: =+AVERAGE(AY4:AY10) -> #DIV/0!
B12: NP Growth | D12: =(D10/C10-1)*100 -> -100 | E12: =(E10/D10-1)*100 -> #DIV/0! | F12: =(F10/E10-1)*100 -> #DIV/0! | G12: =(G10/F10-1)*100 -> #DIV/0! | H12: =(H10/G10-1)*100 -> #DIV/0! | I12: =(I10/H10-1)*100 -> #DIV/0! | J12: =AVERAGE(D12:I12) -> #DIV/0! | S12: 1Q22 | T12: 2Q22 | W12: GPM% | X12: =+X11/X3 -> #DIV/0! | Y12: =+Y11/Y3 -> #DIV/0! | Z12: =+Z11/Z3 -> #DIV/0! | AA12: =+AA11/AA3 -> #DIV/0! | AB12: =+AB11/AB3 -> 0.22198624 | AC12: =+AC11/AC3 -> 0.23473168 | AD12: =+AD11/AD3 -> 0.22757125 | AE12: =+AE11/AE3 -> 0.26267326 | ... AM12: =+AM11/AM3 -> 0.22852306 | AT12: DY | AY12: DY
M13: TTM | N13: =SUM(N8:N11) -> 0 | Q13: =N13*J21 -> #DIV/0! | S13: 19.109574 | T13: 18.873653 | AO13: Leading P/E | AS13: =+$X$1/AS11 -> 10.402612 | AT13: =+AT11/$X$1 -> #DIV/0! | AX13: =+$X$1/AX11 -> 5.3259053 | AY13: =+AY11/$X$1 -> #DIV/0!
